2021-08-24 09:56:27,405 - ERROR - An Error occurred while handling migrations: Traceback (most recent call last):
  File "/Library/Frameworks/Python.framework/Versions/3.9/lib/python3.9/site-packages/pymysql/connections.py", line 613, in connect
    sock = socket.create_connection(
  File "/Library/Frameworks/Python.framework/Versions/3.9/lib/python3.9/socket.py", line 843, in create_connection
    raise err
  File "/Library/Frameworks/Python.framework/Versions/3.9/lib/python3.9/socket.py", line 831, in create_connection
    sock.connect(sa)
TimeoutError: [Errno 60] Operation timed out

During handling of the above exception, another exception occurred:

Traceback (most recent call last):
  File "/Users/pedro_ivo/Fontes/integrator-lwmail/main.py", line 25, in handler_service
    handler_migration = IntegratorService(logger)
  File "/Users/pedro_ivo/Fontes/integrator-lwmail/integrator/service.py", line 20, in __init__
    self.globomail_repository = GlobomailRepository()
  File "/Users/pedro_ivo/Fontes/integrator-lwmail/repositories/globomail.py", line 12, in __init__
    self.connection = pymysql.connect(host=self.hostname, user=self.username, password=self.password,
  File "/Library/Frameworks/Python.framework/Versions/3.9/lib/python3.9/site-packages/pymysql/connections.py", line 353, in __init__
    self.connect()
  File "/Library/Frameworks/Python.framework/Versions/3.9/lib/python3.9/site-packages/pymysql/connections.py", line 664, in connect
    raise exc
pymysql.err.OperationalError: (2003, "Can't connect to MySQL server on 'backendqa0001.globo.correio.biz' ([Errno 60] Operation timed out)")

2021-08-24 09:58:42,844 - ERROR - An Error occurred while handling migrations: Traceback (most recent call last):
  File "/Library/Frameworks/Python.framework/Versions/3.9/lib/python3.9/site-packages/pymysql/connections.py", line 613, in connect
    sock = socket.create_connection(
  File "/Library/Frameworks/Python.framework/Versions/3.9/lib/python3.9/socket.py", line 843, in create_connection
    raise err
  File "/Library/Frameworks/Python.framework/Versions/3.9/lib/python3.9/socket.py", line 831, in create_connection
    sock.connect(sa)
TimeoutError: [Errno 60] Operation timed out

During handling of the above exception, another exception occurred:

Traceback (most recent call last):
  File "/Users/pedro_ivo/Fontes/integrator-lwmail/main.py", line 25, in handler_service
    handler_migration = IntegratorService(logger)
  File "/Users/pedro_ivo/Fontes/integrator-lwmail/integrator/service.py", line 20, in __init__
    self.globomail_repository = GlobomailRepository()
  File "/Users/pedro_ivo/Fontes/integrator-lwmail/repositories/globomail.py", line 12, in __init__
    self.connection = pymysql.connect(host=self.hostname, user=self.username, password=self.password,
  File "/Library/Frameworks/Python.framework/Versions/3.9/lib/python3.9/site-packages/pymysql/connections.py", line 353, in __init__
    self.connect()
  File "/Library/Frameworks/Python.framework/Versions/3.9/lib/python3.9/site-packages/pymysql/connections.py", line 664, in connect
    raise exc
pymysql.err.OperationalError: (2003, "Can't connect to MySQL server on 'backendqa0001.globo.correio.biz' ([Errno 60] Operation timed out)")

2021-08-24 10:00:58,613 - ERROR - An Error occurred while handling migrations: Traceback (most recent call last):
  File "/Library/Frameworks/Python.framework/Versions/3.9/lib/python3.9/site-packages/pymysql/connections.py", line 613, in connect
    sock = socket.create_connection(
  File "/Library/Frameworks/Python.framework/Versions/3.9/lib/python3.9/socket.py", line 843, in create_connection
    raise err
  File "/Library/Frameworks/Python.framework/Versions/3.9/lib/python3.9/socket.py", line 831, in create_connection
    sock.connect(sa)
TimeoutError: [Errno 60] Operation timed out

During handling of the above exception, another exception occurred:

Traceback (most recent call last):
  File "/Users/pedro_ivo/Fontes/integrator-lwmail/main.py", line 25, in handler_service
    handler_migration = IntegratorService(logger)
  File "/Users/pedro_ivo/Fontes/integrator-lwmail/integrator/service.py", line 20, in __init__
    self.globomail_repository = GlobomailRepository()
  File "/Users/pedro_ivo/Fontes/integrator-lwmail/repositories/globomail.py", line 12, in __init__
    self.connection = pymysql.connect(host=self.hostname, user=self.username, password=self.password,
  File "/Library/Frameworks/Python.framework/Versions/3.9/lib/python3.9/site-packages/pymysql/connections.py", line 353, in __init__
    self.connect()
  File "/Library/Frameworks/Python.framework/Versions/3.9/lib/python3.9/site-packages/pymysql/connections.py", line 664, in connect
    raise exc
pymysql.err.OperationalError: (2003, "Can't connect to MySQL server on 'backendqa0001.globo.correio.biz' ([Errno 60] Operation timed out)")

2021-08-24 10:03:14,137 - ERROR - An Error occurred while handling migrations: Traceback (most recent call last):
  File "/Library/Frameworks/Python.framework/Versions/3.9/lib/python3.9/site-packages/pymysql/connections.py", line 613, in connect
    sock = socket.create_connection(
  File "/Library/Frameworks/Python.framework/Versions/3.9/lib/python3.9/socket.py", line 843, in create_connection
    raise err
  File "/Library/Frameworks/Python.framework/Versions/3.9/lib/python3.9/socket.py", line 831, in create_connection
    sock.connect(sa)
TimeoutError: [Errno 60] Operation timed out

During handling of the above exception, another exception occurred:

Traceback (most recent call last):
  File "/Users/pedro_ivo/Fontes/integrator-lwmail/main.py", line 25, in handler_service
    handler_migration = IntegratorService(logger)
  File "/Users/pedro_ivo/Fontes/integrator-lwmail/integrator/service.py", line 20, in __init__
    self.globomail_repository = GlobomailRepository()
  File "/Users/pedro_ivo/Fontes/integrator-lwmail/repositories/globomail.py", line 12, in __init__
    self.connection = pymysql.connect(host=self.hostname, user=self.username, password=self.password,
  File "/Library/Frameworks/Python.framework/Versions/3.9/lib/python3.9/site-packages/pymysql/connections.py", line 353, in __init__
    self.connect()
  File "/Library/Frameworks/Python.framework/Versions/3.9/lib/python3.9/site-packages/pymysql/connections.py", line 664, in connect
    raise exc
pymysql.err.OperationalError: (2003, "Can't connect to MySQL server on 'backendqa0001.globo.correio.biz' ([Errno 60] Operation timed out)")

2021-08-24 10:05:29,607 - ERROR - An Error occurred while handling migrations: Traceback (most recent call last):
  File "/Library/Frameworks/Python.framework/Versions/3.9/lib/python3.9/site-packages/pymysql/connections.py", line 613, in connect
    sock = socket.create_connection(
  File "/Library/Frameworks/Python.framework/Versions/3.9/lib/python3.9/socket.py", line 843, in create_connection
    raise err
  File "/Library/Frameworks/Python.framework/Versions/3.9/lib/python3.9/socket.py", line 831, in create_connection
    sock.connect(sa)
TimeoutError: [Errno 60] Operation timed out

During handling of the above exception, another exception occurred:

Traceback (most recent call last):
  File "/Users/pedro_ivo/Fontes/integrator-lwmail/main.py", line 25, in handler_service
    handler_migration = IntegratorService(logger)
  File "/Users/pedro_ivo/Fontes/integrator-lwmail/integrator/service.py", line 20, in __init__
    self.globomail_repository = GlobomailRepository()
  File "/Users/pedro_ivo/Fontes/integrator-lwmail/repositories/globomail.py", line 12, in __init__
    self.connection = pymysql.connect(host=self.hostname, user=self.username, password=self.password,
  File "/Library/Frameworks/Python.framework/Versions/3.9/lib/python3.9/site-packages/pymysql/connections.py", line 353, in __init__
    self.connect()
  File "/Library/Frameworks/Python.framework/Versions/3.9/lib/python3.9/site-packages/pymysql/connections.py", line 664, in connect
    raise exc
pymysql.err.OperationalError: (2003, "Can't connect to MySQL server on 'backendqa0001.globo.correio.biz' ([Errno 60] Operation timed out)")

2021-08-24 10:07:45,080 - ERROR - An Error occurred while handling migrations: Traceback (most recent call last):
  File "/Library/Frameworks/Python.framework/Versions/3.9/lib/python3.9/site-packages/pymysql/connections.py", line 613, in connect
    sock = socket.create_connection(
  File "/Library/Frameworks/Python.framework/Versions/3.9/lib/python3.9/socket.py", line 843, in create_connection
    raise err
  File "/Library/Frameworks/Python.framework/Versions/3.9/lib/python3.9/socket.py", line 831, in create_connection
    sock.connect(sa)
TimeoutError: [Errno 60] Operation timed out

During handling of the above exception, another exception occurred:

Traceback (most recent call last):
  File "/Users/pedro_ivo/Fontes/integrator-lwmail/main.py", line 25, in handler_service
    handler_migration = IntegratorService(logger)
  File "/Users/pedro_ivo/Fontes/integrator-lwmail/integrator/service.py", line 20, in __init__
    self.globomail_repository = GlobomailRepository()
  File "/Users/pedro_ivo/Fontes/integrator-lwmail/repositories/globomail.py", line 12, in __init__
    self.connection = pymysql.connect(host=self.hostname, user=self.username, password=self.password,
  File "/Library/Frameworks/Python.framework/Versions/3.9/lib/python3.9/site-packages/pymysql/connections.py", line 353, in __init__
    self.connect()
  File "/Library/Frameworks/Python.framework/Versions/3.9/lib/python3.9/site-packages/pymysql/connections.py", line 664, in connect
    raise exc
pymysql.err.OperationalError: (2003, "Can't connect to MySQL server on 'backendqa0001.globo.correio.biz' ([Errno 60] Operation timed out)")

2021-08-24 10:10:00,550 - ERROR - An Error occurred while handling migrations: Traceback (most recent call last):
  File "/Library/Frameworks/Python.framework/Versions/3.9/lib/python3.9/site-packages/pymysql/connections.py", line 613, in connect
    sock = socket.create_connection(
  File "/Library/Frameworks/Python.framework/Versions/3.9/lib/python3.9/socket.py", line 843, in create_connection
    raise err
  File "/Library/Frameworks/Python.framework/Versions/3.9/lib/python3.9/socket.py", line 831, in create_connection
    sock.connect(sa)
TimeoutError: [Errno 60] Operation timed out

During handling of the above exception, another exception occurred:

Traceback (most recent call last):
  File "/Users/pedro_ivo/Fontes/integrator-lwmail/main.py", line 25, in handler_service
    handler_migration = IntegratorService(logger)
  File "/Users/pedro_ivo/Fontes/integrator-lwmail/integrator/service.py", line 20, in __init__
    self.globomail_repository = GlobomailRepository()
  File "/Users/pedro_ivo/Fontes/integrator-lwmail/repositories/globomail.py", line 12, in __init__
    self.connection = pymysql.connect(host=self.hostname, user=self.username, password=self.password,
  File "/Library/Frameworks/Python.framework/Versions/3.9/lib/python3.9/site-packages/pymysql/connections.py", line 353, in __init__
    self.connect()
  File "/Library/Frameworks/Python.framework/Versions/3.9/lib/python3.9/site-packages/pymysql/connections.py", line 664, in connect
    raise exc
pymysql.err.OperationalError: (2003, "Can't connect to MySQL server on 'backendqa0001.globo.correio.biz' ([Errno 60] Operation timed out)")

2021-08-24 10:12:16,020 - ERROR - An Error occurred while handling migrations: Traceback (most recent call last):
  File "/Library/Frameworks/Python.framework/Versions/3.9/lib/python3.9/site-packages/pymysql/connections.py", line 613, in connect
    sock = socket.create_connection(
  File "/Library/Frameworks/Python.framework/Versions/3.9/lib/python3.9/socket.py", line 843, in create_connection
    raise err
  File "/Library/Frameworks/Python.framework/Versions/3.9/lib/python3.9/socket.py", line 831, in create_connection
    sock.connect(sa)
TimeoutError: [Errno 60] Operation timed out

During handling of the above exception, another exception occurred:

Traceback (most recent call last):
  File "/Users/pedro_ivo/Fontes/integrator-lwmail/main.py", line 25, in handler_service
    handler_migration = IntegratorService(logger)
  File "/Users/pedro_ivo/Fontes/integrator-lwmail/integrator/service.py", line 20, in __init__
    self.globomail_repository = GlobomailRepository()
  File "/Users/pedro_ivo/Fontes/integrator-lwmail/repositories/globomail.py", line 12, in __init__
    self.connection = pymysql.connect(host=self.hostname, user=self.username, password=self.password,
  File "/Library/Frameworks/Python.framework/Versions/3.9/lib/python3.9/site-packages/pymysql/connections.py", line 353, in __init__
    self.connect()
  File "/Library/Frameworks/Python.framework/Versions/3.9/lib/python3.9/site-packages/pymysql/connections.py", line 664, in connect
    raise exc
pymysql.err.OperationalError: (2003, "Can't connect to MySQL server on 'backendqa0001.globo.correio.biz' ([Errno 60] Operation timed out)")

2021-08-24 10:14:31,485 - ERROR - An Error occurred while handling migrations: Traceback (most recent call last):
  File "/Library/Frameworks/Python.framework/Versions/3.9/lib/python3.9/site-packages/pymysql/connections.py", line 613, in connect
    sock = socket.create_connection(
  File "/Library/Frameworks/Python.framework/Versions/3.9/lib/python3.9/socket.py", line 843, in create_connection
    raise err
  File "/Library/Frameworks/Python.framework/Versions/3.9/lib/python3.9/socket.py", line 831, in create_connection
    sock.connect(sa)
TimeoutError: [Errno 60] Operation timed out

During handling of the above exception, another exception occurred:

Traceback (most recent call last):
  File "/Users/pedro_ivo/Fontes/integrator-lwmail/main.py", line 25, in handler_service
    handler_migration = IntegratorService(logger)
  File "/Users/pedro_ivo/Fontes/integrator-lwmail/integrator/service.py", line 20, in __init__
    self.globomail_repository = GlobomailRepository()
  File "/Users/pedro_ivo/Fontes/integrator-lwmail/repositories/globomail.py", line 12, in __init__
    self.connection = pymysql.connect(host=self.hostname, user=self.username, password=self.password,
  File "/Library/Frameworks/Python.framework/Versions/3.9/lib/python3.9/site-packages/pymysql/connections.py", line 353, in __init__
    self.connect()
  File "/Library/Frameworks/Python.framework/Versions/3.9/lib/python3.9/site-packages/pymysql/connections.py", line 664, in connect
    raise exc
pymysql.err.OperationalError: (2003, "Can't connect to MySQL server on 'backendqa0001.globo.correio.biz' ([Errno 60] Operation timed out)")

2021-08-24 10:16:46,952 - ERROR - An Error occurred while handling migrations: Traceback (most recent call last):
  File "/Library/Frameworks/Python.framework/Versions/3.9/lib/python3.9/site-packages/pymysql/connections.py", line 613, in connect
    sock = socket.create_connection(
  File "/Library/Frameworks/Python.framework/Versions/3.9/lib/python3.9/socket.py", line 843, in create_connection
    raise err
  File "/Library/Frameworks/Python.framework/Versions/3.9/lib/python3.9/socket.py", line 831, in create_connection
    sock.connect(sa)
TimeoutError: [Errno 60] Operation timed out

During handling of the above exception, another exception occurred:

Traceback (most recent call last):
  File "/Users/pedro_ivo/Fontes/integrator-lwmail/main.py", line 25, in handler_service
    handler_migration = IntegratorService(logger)
  File "/Users/pedro_ivo/Fontes/integrator-lwmail/integrator/service.py", line 20, in __init__
    self.globomail_repository = GlobomailRepository()
  File "/Users/pedro_ivo/Fontes/integrator-lwmail/repositories/globomail.py", line 12, in __init__
    self.connection = pymysql.connect(host=self.hostname, user=self.username, password=self.password,
  File "/Library/Frameworks/Python.framework/Versions/3.9/lib/python3.9/site-packages/pymysql/connections.py", line 353, in __init__
    self.connect()
  File "/Library/Frameworks/Python.framework/Versions/3.9/lib/python3.9/site-packages/pymysql/connections.py", line 664, in connect
    raise exc
pymysql.err.OperationalError: (2003, "Can't connect to MySQL server on 'backendqa0001.globo.correio.biz' ([Errno 60] Operation timed out)")

2021-08-24 10:19:02,384 - ERROR - An Error occurred while handling migrations: Traceback (most recent call last):
  File "/Library/Frameworks/Python.framework/Versions/3.9/lib/python3.9/site-packages/pymysql/connections.py", line 613, in connect
    sock = socket.create_connection(
  File "/Library/Frameworks/Python.framework/Versions/3.9/lib/python3.9/socket.py", line 843, in create_connection
    raise err
  File "/Library/Frameworks/Python.framework/Versions/3.9/lib/python3.9/socket.py", line 831, in create_connection
    sock.connect(sa)
TimeoutError: [Errno 60] Operation timed out

During handling of the above exception, another exception occurred:

Traceback (most recent call last):
  File "/Users/pedro_ivo/Fontes/integrator-lwmail/main.py", line 25, in handler_service
    handler_migration = IntegratorService(logger)
  File "/Users/pedro_ivo/Fontes/integrator-lwmail/integrator/service.py", line 20, in __init__
    self.globomail_repository = GlobomailRepository()
  File "/Users/pedro_ivo/Fontes/integrator-lwmail/repositories/globomail.py", line 12, in __init__
    self.connection = pymysql.connect(host=self.hostname, user=self.username, password=self.password,
  File "/Library/Frameworks/Python.framework/Versions/3.9/lib/python3.9/site-packages/pymysql/connections.py", line 353, in __init__
    self.connect()
  File "/Library/Frameworks/Python.framework/Versions/3.9/lib/python3.9/site-packages/pymysql/connections.py", line 664, in connect
    raise exc
pymysql.err.OperationalError: (2003, "Can't connect to MySQL server on 'backendqa0001.globo.correio.biz' ([Errno 60] Operation timed out)")

2021-08-24 10:21:18,039 - ERROR - An Error occurred while handling migrations: Traceback (most recent call last):
  File "/Library/Frameworks/Python.framework/Versions/3.9/lib/python3.9/site-packages/pymysql/connections.py", line 613, in connect
    sock = socket.create_connection(
  File "/Library/Frameworks/Python.framework/Versions/3.9/lib/python3.9/socket.py", line 843, in create_connection
    raise err
  File "/Library/Frameworks/Python.framework/Versions/3.9/lib/python3.9/socket.py", line 831, in create_connection
    sock.connect(sa)
TimeoutError: [Errno 60] Operation timed out

During handling of the above exception, another exception occurred:

Traceback (most recent call last):
  File "/Users/pedro_ivo/Fontes/integrator-lwmail/main.py", line 25, in handler_service
    handler_migration = IntegratorService(logger)
  File "/Users/pedro_ivo/Fontes/integrator-lwmail/integrator/service.py", line 20, in __init__
    self.globomail_repository = GlobomailRepository()
  File "/Users/pedro_ivo/Fontes/integrator-lwmail/repositories/globomail.py", line 12, in __init__
    self.connection = pymysql.connect(host=self.hostname, user=self.username, password=self.password,
  File "/Library/Frameworks/Python.framework/Versions/3.9/lib/python3.9/site-packages/pymysql/connections.py", line 353, in __init__
    self.connect()
  File "/Library/Frameworks/Python.framework/Versions/3.9/lib/python3.9/site-packages/pymysql/connections.py", line 664, in connect
    raise exc
pymysql.err.OperationalError: (2003, "Can't connect to MySQL server on 'backendqa0001.globo.correio.biz' ([Errno 60] Operation timed out)")

2021-08-24 10:23:33,493 - ERROR - An Error occurred while handling migrations: Traceback (most recent call last):
  File "/Library/Frameworks/Python.framework/Versions/3.9/lib/python3.9/site-packages/pymysql/connections.py", line 613, in connect
    sock = socket.create_connection(
  File "/Library/Frameworks/Python.framework/Versions/3.9/lib/python3.9/socket.py", line 843, in create_connection
    raise err
  File "/Library/Frameworks/Python.framework/Versions/3.9/lib/python3.9/socket.py", line 831, in create_connection
    sock.connect(sa)
TimeoutError: [Errno 60] Operation timed out

During handling of the above exception, another exception occurred:

Traceback (most recent call last):
  File "/Users/pedro_ivo/Fontes/integrator-lwmail/main.py", line 25, in handler_service
    handler_migration = IntegratorService(logger)
  File "/Users/pedro_ivo/Fontes/integrator-lwmail/integrator/service.py", line 20, in __init__
    self.globomail_repository = GlobomailRepository()
  File "/Users/pedro_ivo/Fontes/integrator-lwmail/repositories/globomail.py", line 12, in __init__
    self.connection = pymysql.connect(host=self.hostname, user=self.username, password=self.password,
  File "/Library/Frameworks/Python.framework/Versions/3.9/lib/python3.9/site-packages/pymysql/connections.py", line 353, in __init__
    self.connect()
  File "/Library/Frameworks/Python.framework/Versions/3.9/lib/python3.9/site-packages/pymysql/connections.py", line 664, in connect
    raise exc
pymysql.err.OperationalError: (2003, "Can't connect to MySQL server on 'backendqa0001.globo.correio.biz' ([Errno 60] Operation timed out)")

2021-08-24 10:25:48,918 - ERROR - An Error occurred while handling migrations: Traceback (most recent call last):
  File "/Library/Frameworks/Python.framework/Versions/3.9/lib/python3.9/site-packages/pymysql/connections.py", line 613, in connect
    sock = socket.create_connection(
  File "/Library/Frameworks/Python.framework/Versions/3.9/lib/python3.9/socket.py", line 843, in create_connection
    raise err
  File "/Library/Frameworks/Python.framework/Versions/3.9/lib/python3.9/socket.py", line 831, in create_connection
    sock.connect(sa)
TimeoutError: [Errno 60] Operation timed out

During handling of the above exception, another exception occurred:

Traceback (most recent call last):
  File "/Users/pedro_ivo/Fontes/integrator-lwmail/main.py", line 25, in handler_service
    handler_migration = IntegratorService(logger)
  File "/Users/pedro_ivo/Fontes/integrator-lwmail/integrator/service.py", line 20, in __init__
    self.globomail_repository = GlobomailRepository()
  File "/Users/pedro_ivo/Fontes/integrator-lwmail/repositories/globomail.py", line 12, in __init__
    self.connection = pymysql.connect(host=self.hostname, user=self.username, password=self.password,
  File "/Library/Frameworks/Python.framework/Versions/3.9/lib/python3.9/site-packages/pymysql/connections.py", line 353, in __init__
    self.connect()
  File "/Library/Frameworks/Python.framework/Versions/3.9/lib/python3.9/site-packages/pymysql/connections.py", line 664, in connect
    raise exc
pymysql.err.OperationalError: (2003, "Can't connect to MySQL server on 'backendqa0001.globo.correio.biz' ([Errno 60] Operation timed out)")

2021-08-24 10:28:04,374 - ERROR - An Error occurred while handling migrations: Traceback (most recent call last):
  File "/Library/Frameworks/Python.framework/Versions/3.9/lib/python3.9/site-packages/pymysql/connections.py", line 613, in connect
    sock = socket.create_connection(
  File "/Library/Frameworks/Python.framework/Versions/3.9/lib/python3.9/socket.py", line 843, in create_connection
    raise err
  File "/Library/Frameworks/Python.framework/Versions/3.9/lib/python3.9/socket.py", line 831, in create_connection
    sock.connect(sa)
TimeoutError: [Errno 60] Operation timed out

During handling of the above exception, another exception occurred:

Traceback (most recent call last):
  File "/Users/pedro_ivo/Fontes/integrator-lwmail/main.py", line 25, in handler_service
    handler_migration = IntegratorService(logger)
  File "/Users/pedro_ivo/Fontes/integrator-lwmail/integrator/service.py", line 20, in __init__
    self.globomail_repository = GlobomailRepository()
  File "/Users/pedro_ivo/Fontes/integrator-lwmail/repositories/globomail.py", line 12, in __init__
    self.connection = pymysql.connect(host=self.hostname, user=self.username, password=self.password,
  File "/Library/Frameworks/Python.framework/Versions/3.9/lib/python3.9/site-packages/pymysql/connections.py", line 353, in __init__
    self.connect()
  File "/Library/Frameworks/Python.framework/Versions/3.9/lib/python3.9/site-packages/pymysql/connections.py", line 664, in connect
    raise exc
pymysql.err.OperationalError: (2003, "Can't connect to MySQL server on 'backendqa0001.globo.correio.biz' ([Errno 60] Operation timed out)")

2021-08-24 10:30:19,833 - ERROR - An Error occurred while handling migrations: Traceback (most recent call last):
  File "/Library/Frameworks/Python.framework/Versions/3.9/lib/python3.9/site-packages/pymysql/connections.py", line 613, in connect
    sock = socket.create_connection(
  File "/Library/Frameworks/Python.framework/Versions/3.9/lib/python3.9/socket.py", line 843, in create_connection
    raise err
  File "/Library/Frameworks/Python.framework/Versions/3.9/lib/python3.9/socket.py", line 831, in create_connection
    sock.connect(sa)
TimeoutError: [Errno 60] Operation timed out

During handling of the above exception, another exception occurred:

Traceback (most recent call last):
  File "/Users/pedro_ivo/Fontes/integrator-lwmail/main.py", line 25, in handler_service
    handler_migration = IntegratorService(logger)
  File "/Users/pedro_ivo/Fontes/integrator-lwmail/integrator/service.py", line 20, in __init__
    self.globomail_repository = GlobomailRepository()
  File "/Users/pedro_ivo/Fontes/integrator-lwmail/repositories/globomail.py", line 12, in __init__
    self.connection = pymysql.connect(host=self.hostname, user=self.username, password=self.password,
  File "/Library/Frameworks/Python.framework/Versions/3.9/lib/python3.9/site-packages/pymysql/connections.py", line 353, in __init__
    self.connect()
  File "/Library/Frameworks/Python.framework/Versions/3.9/lib/python3.9/site-packages/pymysql/connections.py", line 664, in connect
    raise exc
pymysql.err.OperationalError: (2003, "Can't connect to MySQL server on 'backendqa0001.globo.correio.biz' ([Errno 60] Operation timed out)")

2021-08-24 10:32:35,353 - ERROR - An Error occurred while handling migrations: Traceback (most recent call last):
  File "/Library/Frameworks/Python.framework/Versions/3.9/lib/python3.9/site-packages/pymysql/connections.py", line 613, in connect
    sock = socket.create_connection(
  File "/Library/Frameworks/Python.framework/Versions/3.9/lib/python3.9/socket.py", line 843, in create_connection
    raise err
  File "/Library/Frameworks/Python.framework/Versions/3.9/lib/python3.9/socket.py", line 831, in create_connection
    sock.connect(sa)
TimeoutError: [Errno 60] Operation timed out

During handling of the above exception, another exception occurred:

Traceback (most recent call last):
  File "/Users/pedro_ivo/Fontes/integrator-lwmail/main.py", line 25, in handler_service
    handler_migration = IntegratorService(logger)
  File "/Users/pedro_ivo/Fontes/integrator-lwmail/integrator/service.py", line 20, in __init__
    self.globomail_repository = GlobomailRepository()
  File "/Users/pedro_ivo/Fontes/integrator-lwmail/repositories/globomail.py", line 12, in __init__
    self.connection = pymysql.connect(host=self.hostname, user=self.username, password=self.password,
  File "/Library/Frameworks/Python.framework/Versions/3.9/lib/python3.9/site-packages/pymysql/connections.py", line 353, in __init__
    self.connect()
  File "/Library/Frameworks/Python.framework/Versions/3.9/lib/python3.9/site-packages/pymysql/connections.py", line 664, in connect
    raise exc
pymysql.err.OperationalError: (2003, "Can't connect to MySQL server on 'backendqa0001.globo.correio.biz' ([Errno 60] Operation timed out)")

2021-08-24 10:34:50,986 - ERROR - An Error occurred while handling migrations: Traceback (most recent call last):
  File "/Library/Frameworks/Python.framework/Versions/3.9/lib/python3.9/site-packages/pymysql/connections.py", line 613, in connect
    sock = socket.create_connection(
  File "/Library/Frameworks/Python.framework/Versions/3.9/lib/python3.9/socket.py", line 843, in create_connection
    raise err
  File "/Library/Frameworks/Python.framework/Versions/3.9/lib/python3.9/socket.py", line 831, in create_connection
    sock.connect(sa)
TimeoutError: [Errno 60] Operation timed out

During handling of the above exception, another exception occurred:

Traceback (most recent call last):
  File "/Users/pedro_ivo/Fontes/integrator-lwmail/main.py", line 25, in handler_service
    handler_migration = IntegratorService(logger)
  File "/Users/pedro_ivo/Fontes/integrator-lwmail/integrator/service.py", line 20, in __init__
    self.globomail_repository = GlobomailRepository()
  File "/Users/pedro_ivo/Fontes/integrator-lwmail/repositories/globomail.py", line 12, in __init__
    self.connection = pymysql.connect(host=self.hostname, user=self.username, password=self.password,
  File "/Library/Frameworks/Python.framework/Versions/3.9/lib/python3.9/site-packages/pymysql/connections.py", line 353, in __init__
    self.connect()
  File "/Library/Frameworks/Python.framework/Versions/3.9/lib/python3.9/site-packages/pymysql/connections.py", line 664, in connect
    raise exc
pymysql.err.OperationalError: (2003, "Can't connect to MySQL server on 'backendqa0001.globo.correio.biz' ([Errno 60] Operation timed out)")

2021-08-24 10:37:06,550 - ERROR - An Error occurred while handling migrations: Traceback (most recent call last):
  File "/Library/Frameworks/Python.framework/Versions/3.9/lib/python3.9/site-packages/pymysql/connections.py", line 613, in connect
    sock = socket.create_connection(
  File "/Library/Frameworks/Python.framework/Versions/3.9/lib/python3.9/socket.py", line 843, in create_connection
    raise err
  File "/Library/Frameworks/Python.framework/Versions/3.9/lib/python3.9/socket.py", line 831, in create_connection
    sock.connect(sa)
TimeoutError: [Errno 60] Operation timed out

During handling of the above exception, another exception occurred:

Traceback (most recent call last):
  File "/Users/pedro_ivo/Fontes/integrator-lwmail/main.py", line 25, in handler_service
    handler_migration = IntegratorService(logger)
  File "/Users/pedro_ivo/Fontes/integrator-lwmail/integrator/service.py", line 20, in __init__
    self.globomail_repository = GlobomailRepository()
  File "/Users/pedro_ivo/Fontes/integrator-lwmail/repositories/globomail.py", line 12, in __init__
    self.connection = pymysql.connect(host=self.hostname, user=self.username, password=self.password,
  File "/Library/Frameworks/Python.framework/Versions/3.9/lib/python3.9/site-packages/pymysql/connections.py", line 353, in __init__
    self.connect()
  File "/Library/Frameworks/Python.framework/Versions/3.9/lib/python3.9/site-packages/pymysql/connections.py", line 664, in connect
    raise exc
pymysql.err.OperationalError: (2003, "Can't connect to MySQL server on 'backendqa0001.globo.correio.biz' ([Errno 60] Operation timed out)")

2021-08-24 10:39:22,186 - ERROR - An Error occurred while handling migrations: Traceback (most recent call last):
  File "/Library/Frameworks/Python.framework/Versions/3.9/lib/python3.9/site-packages/pymysql/connections.py", line 613, in connect
    sock = socket.create_connection(
  File "/Library/Frameworks/Python.framework/Versions/3.9/lib/python3.9/socket.py", line 843, in create_connection
    raise err
  File "/Library/Frameworks/Python.framework/Versions/3.9/lib/python3.9/socket.py", line 831, in create_connection
    sock.connect(sa)
TimeoutError: [Errno 60] Operation timed out

During handling of the above exception, another exception occurred:

Traceback (most recent call last):
  File "/Users/pedro_ivo/Fontes/integrator-lwmail/main.py", line 25, in handler_service
    handler_migration = IntegratorService(logger)
  File "/Users/pedro_ivo/Fontes/integrator-lwmail/integrator/service.py", line 20, in __init__
    self.globomail_repository = GlobomailRepository()
  File "/Users/pedro_ivo/Fontes/integrator-lwmail/repositories/globomail.py", line 12, in __init__
    self.connection = pymysql.connect(host=self.hostname, user=self.username, password=self.password,
  File "/Library/Frameworks/Python.framework/Versions/3.9/lib/python3.9/site-packages/pymysql/connections.py", line 353, in __init__
    self.connect()
  File "/Library/Frameworks/Python.framework/Versions/3.9/lib/python3.9/site-packages/pymysql/connections.py", line 664, in connect
    raise exc
pymysql.err.OperationalError: (2003, "Can't connect to MySQL server on 'backendqa0001.globo.correio.biz' ([Errno 60] Operation timed out)")

2021-08-24 10:41:37,894 - ERROR - An Error occurred while handling migrations: Traceback (most recent call last):
  File "/Library/Frameworks/Python.framework/Versions/3.9/lib/python3.9/site-packages/pymysql/connections.py", line 613, in connect
    sock = socket.create_connection(
  File "/Library/Frameworks/Python.framework/Versions/3.9/lib/python3.9/socket.py", line 843, in create_connection
    raise err
  File "/Library/Frameworks/Python.framework/Versions/3.9/lib/python3.9/socket.py", line 831, in create_connection
    sock.connect(sa)
TimeoutError: [Errno 60] Operation timed out

During handling of the above exception, another exception occurred:

Traceback (most recent call last):
  File "/Users/pedro_ivo/Fontes/integrator-lwmail/main.py", line 25, in handler_service
    handler_migration = IntegratorService(logger)
  File "/Users/pedro_ivo/Fontes/integrator-lwmail/integrator/service.py", line 20, in __init__
    self.globomail_repository = GlobomailRepository()
  File "/Users/pedro_ivo/Fontes/integrator-lwmail/repositories/globomail.py", line 12, in __init__
    self.connection = pymysql.connect(host=self.hostname, user=self.username, password=self.password,
  File "/Library/Frameworks/Python.framework/Versions/3.9/lib/python3.9/site-packages/pymysql/connections.py", line 353, in __init__
    self.connect()
  File "/Library/Frameworks/Python.framework/Versions/3.9/lib/python3.9/site-packages/pymysql/connections.py", line 664, in connect
    raise exc
pymysql.err.OperationalError: (2003, "Can't connect to MySQL server on 'backendqa0001.globo.correio.biz' ([Errno 60] Operation timed out)")

2021-08-24 10:42:38,643 - INFO - starting integration process for new email migrations
2021-08-24 10:43:39,778 - INFO - starting integration process for new email migrations
2021-08-24 10:44:41,011 - INFO - starting integration process for new email migrations
2021-08-24 10:45:42,561 - INFO - starting integration process for new email migrations
2021-08-24 10:46:43,679 - INFO - starting integration process for new email migrations
2021-08-24 10:47:44,810 - INFO - starting integration process for new email migrations
2021-08-24 10:48:45,937 - INFO - starting integration process for new email migrations
2021-08-24 10:49:47,101 - INFO - starting integration process for new email migrations
2021-08-24 10:50:48,232 - INFO - starting integration process for new email migrations
2021-08-24 10:51:49,368 - INFO - starting integration process for new email migrations
2021-08-24 10:52:50,608 - INFO - starting integration process for new email migrations
2021-08-24 10:53:51,794 - INFO - starting integration process for new email migrations
2021-08-24 10:54:52,919 - INFO - starting integration process for new email migrations
2021-08-24 10:55:54,169 - INFO - starting integration process for new email migrations
2021-08-24 10:56:55,305 - INFO - starting integration process for new email migrations
2021-08-24 10:57:56,454 - INFO - starting integration process for new email migrations
2021-08-24 10:58:57,557 - INFO - starting integration process for new email migrations
2021-08-24 11:01:17,160 - ERROR - An Error occurred while handling migrations: Traceback (most recent call last):
  File "/Library/Frameworks/Python.framework/Versions/3.9/lib/python3.9/site-packages/pymysql/connections.py", line 613, in connect
    sock = socket.create_connection(
  File "/Library/Frameworks/Python.framework/Versions/3.9/lib/python3.9/socket.py", line 843, in create_connection
    raise err
  File "/Library/Frameworks/Python.framework/Versions/3.9/lib/python3.9/socket.py", line 831, in create_connection
    sock.connect(sa)
TimeoutError: [Errno 60] Operation timed out

During handling of the above exception, another exception occurred:

Traceback (most recent call last):
  File "/Users/pedro_ivo/Fontes/integrator-lwmail/main.py", line 25, in handler_service
    handler_migration = IntegratorService(logger)
  File "/Users/pedro_ivo/Fontes/integrator-lwmail/integrator/service.py", line 20, in __init__
    self.globomail_repository = GlobomailRepository()
  File "/Users/pedro_ivo/Fontes/integrator-lwmail/repositories/globomail.py", line 12, in __init__
    self.connection = pymysql.connect(host=self.hostname, user=self.username, password=self.password,
  File "/Library/Frameworks/Python.framework/Versions/3.9/lib/python3.9/site-packages/pymysql/connections.py", line 353, in __init__
    self.connect()
  File "/Library/Frameworks/Python.framework/Versions/3.9/lib/python3.9/site-packages/pymysql/connections.py", line 664, in connect
    raise exc
pymysql.err.OperationalError: (2003, "Can't connect to MySQL server on 'backendqa0001.globo.correio.biz' ([Errno 60] Operation timed out)")

2021-08-24 11:02:17,917 - INFO - starting integration process for new email migrations
2021-08-24 11:03:19,136 - INFO - starting integration process for new email migrations
2021-08-24 11:04:20,268 - INFO - starting integration process for new email migrations
2021-08-24 11:05:21,478 - INFO - starting integration process for new email migrations
2021-08-24 11:06:22,621 - INFO - starting integration process for new email migrations
2021-08-24 11:07:23,805 - INFO - starting integration process for new email migrations
2021-08-24 11:08:24,937 - INFO - starting integration process for new email migrations
2021-08-24 11:09:26,162 - INFO - starting integration process for new email migrations
2021-08-24 11:10:27,277 - INFO - starting integration process for new email migrations
