2021-08-09 19:12:02,740 - INFO - starting integration process for new email migrations
2021-08-09 19:12:03,330 - INFO - starting migration for id_globo: C09999
2021-08-09 19:12:15,890 - INFO - sending notification: {'name': 'customer/pt-br/create', 'data': {'login': None, 'channels': ['email'], 'customer_workbench_uri': 'https://centraldocliente.locaweb.com.br', 'assets_uri': 'https://assets.locaweb.com.br'}, 'recipients': [{'customer_id': '1100028375', 'emails': ['t.bdd.20160504173841@qa.globoi.com', 'danilo.kramel@envolti.com.br', 'danilokramel@gmail.com', 'pedro.santana@envolti.com.br']}], 'channels': ['email']} to https://notifications.systemintegration.locaweb.com.br with headers: {'Service-Ticket': 'ST-771597--GwJWLdedZGZmIKaFdElv48Sxi4cas53-elisa', 'Content-Type': 'application/json'}
2021-08-09 19:12:17,521 - INFO - id_globo: C09999 successfully migrated
2021-08-09 19:13:18,186 - INFO - starting integration process for new email migrations
2021-08-09 19:14:19,464 - INFO - starting integration process for new email migrations
2021-08-09 19:15:20,625 - INFO - starting integration process for new email migrations
2021-08-09 19:16:21,943 - INFO - starting integration process for new email migrations
2021-08-09 19:20:45,761 - INFO - starting integration process for new email migrations
2021-08-09 19:20:46,319 - INFO - starting migration for id_globo: Y09999
2021-08-09 19:20:57,449 - INFO - sending notification: {'name': 'customer/pt-br/create', 'data': {'login': 'caioazultes49594', 'channels': ['email'], 'customer_workbench_uri': 'https://centraldocliente.locaweb.com.br', 'assets_uri': 'https://assets.locaweb.com.br'}, 'recipients': [{'customer_id': '1100028376', 'emails': ['t.bdd.20160504173804@qa.globoi.com', 'danilo.kramel@envolti.com.br', 'danilokramel@gmail.com', 'pedro.santana@envolti.com.br']}], 'channels': ['email']} to https://notifications.systemintegration.locaweb.com.br with headers: {'Service-Ticket': 'ST-774862-RfLF-mt96W-mwZ7WIHAOKZaoARccas53-elisa', 'Content-Type': 'application/json'}
2021-08-09 19:20:58,426 - INFO - id_globo: Y09999 successfully migrated
2021-08-09 19:21:59,033 - INFO - starting integration process for new email migrations
2021-08-09 19:23:00,287 - INFO - starting integration process for new email migrations
2021-08-09 19:24:01,441 - INFO - starting integration process for new email migrations
2021-08-09 19:25:02,708 - INFO - starting integration process for new email migrations
2021-08-09 19:26:03,881 - INFO - starting integration process for new email migrations
2021-08-09 19:27:05,137 - INFO - starting integration process for new email migrations
2021-08-09 19:28:06,355 - INFO - starting integration process for new email migrations
2021-08-09 19:31:06,632 - INFO - starting integration process for new email migrations
2021-08-09 19:31:07,236 - INFO - starting migration for id_globo: W09999
2021-08-09 19:31:11,369 - INFO - quota: {quota}
2021-08-09 19:31:11,374 - INFO - plan: {plan}
2021-08-09 19:32:15,461 - INFO - starting integration process for new email migrations
2021-08-09 19:35:48,502 - INFO - starting integration process for new email migrations
2021-08-09 19:36:49,880 - INFO - starting integration process for new email migrations
2021-08-09 19:36:50,621 - INFO - starting migration for id_globo: I09999
2021-08-09 19:36:54,718 - INFO - quota - 20480
2021-08-09 19:36:54,731 - INFO - plan - {'plan_id': 'e2e9f180-655f-4385-b54e-992ff86a8bfe', 'plan_value': 10.0}
2021-08-09 19:37:05,469 - INFO - sending notification: {'name': 'customer/pt-br/create', 'data': {'login': 'tvazulteste69430', 'channels': ['email'], 'customer_workbench_uri': 'https://centraldocliente.locaweb.com.br', 'assets_uri': 'https://assets.locaweb.com.br'}, 'recipients': [{'customer_id': '1100028378', 'emails': ['t.bdd.20160518103907@qa.globoi.com', 'danilo.kramel@envolti.com.br', 'danilokramel@gmail.com', 'pedro.santana@envolti.com.br']}], 'channels': ['email']} to https://notifications.systemintegration.locaweb.com.br with headers: {'Service-Ticket': 'ST-775765-3sfEBY9kFrQouGYcjCopW9n1qNscas53-elisa', 'Content-Type': 'application/json'}
2021-08-09 19:37:06,090 - INFO - id_globo: I09999 successfully migrated
2021-08-09 19:38:06,723 - INFO - starting integration process for new email migrations
2021-08-09 19:39:07,978 - INFO - starting integration process for new email migrations
2021-08-09 19:40:09,227 - INFO - starting integration process for new email migrations
2021-08-09 19:41:10,564 - INFO - starting integration process for new email migrations
2021-08-09 19:44:16,162 - INFO - starting integration process for new email migrations
2021-08-09 19:44:16,843 - INFO - starting migration for id_globo: I08888
2021-08-09 19:44:20,916 - INFO - quota - 20480
2021-08-09 19:44:20,923 - INFO - plan - {'plan_id': 'e2e9f180-655f-4385-b54e-992ff86a8bfe', 'plan_value': 10.0}
2021-08-09 19:44:27,406 - ERROR - {"error":"customer locaweb.danilo already exists"}
2021-08-09 19:45:28,483 - INFO - starting integration process for new email migrations
2021-08-09 19:53:44,869 - INFO - starting integration process for new email migrations
2021-08-09 19:53:46,221 - INFO - starting migration for id_globo: I0777
2021-08-09 19:53:50,745 - INFO - quota - 20480
2021-08-09 19:53:50,750 - INFO - plan - {'plan_id': 'b7c48522-a5b6-4de9-ae2e-78aaaec9d02f', 'plan_value': 1.0}
2021-08-09 19:53:58,480 - INFO - sending notification: {'name': 'customer/pt-br/create', 'data': {'login': 'portaazulte32231', 'channels': ['email'], 'customer_workbench_uri': 'https://centraldocliente.locaweb.com.br', 'assets_uri': 'https://assets.locaweb.com.br'}, 'recipients': [{'customer_id': '1100028380', 'emails': ['teste.depesememail@qa.globoi.com', 'danilo.kramel@envolti.com.br', 'danilokramel@gmail.com', 'pedro.santana@envolti.com.br']}], 'channels': ['email']} to https://notifications.systemintegration.locaweb.com.br with headers: {'Service-Ticket': 'ST-776727-tMcbltKVch70rsa-McZGlLFvKC4cas53-elisa', 'Content-Type': 'application/json'}
2021-08-09 19:53:59,062 - INFO - id_globo: I0777 successfully migrated
2021-08-09 19:54:59,736 - INFO - starting integration process for new email migrations
2021-08-09 19:56:00,912 - INFO - starting integration process for new email migrations
2021-08-09 19:57:02,826 - INFO - starting integration process for new email migrations
2021-08-09 19:58:03,975 - INFO - starting integration process for new email migrations
2021-08-09 19:59:05,238 - INFO - starting integration process for new email migrations
2021-08-09 20:00:06,524 - INFO - starting integration process for new email migrations
2021-08-09 20:01:07,830 - INFO - starting integration process for new email migrations
2021-08-09 20:02:08,994 - INFO - starting integration process for new email migrations
2021-08-09 20:03:10,328 - INFO - starting integration process for new email migrations
2021-08-09 20:04:11,590 - INFO - starting integration process for new email migrations
2021-08-09 20:40:02,426 - ERROR - An Error occurred while handling migrations: Traceback (most recent call last):
  File "/usr/local/lib/python3.8/site-packages/pymysql/connections.py", line 613, in connect
    sock = socket.create_connection(
  File "/usr/local/lib/python3.8/socket.py", line 808, in create_connection
    raise err
  File "/usr/local/lib/python3.8/socket.py", line 796, in create_connection
    sock.connect(sa)
socket.timeout: timed out

During handling of the above exception, another exception occurred:

Traceback (most recent call last):
  File "main.py", line 25, in handler_service
    handler_migration = IntegratorService(logger)
  File "/opt/globo/integrator/service.py", line 20, in __init__
    self.globomail_repository = GlobomailRepository()
  File "/opt/globo/repositories/globomail.py", line 12, in __init__
    self.connection = pymysql.connect(host=self.hostname, user=self.username, password=self.password,
  File "/usr/local/lib/python3.8/site-packages/pymysql/connections.py", line 353, in __init__
    self.connect()
  File "/usr/local/lib/python3.8/site-packages/pymysql/connections.py", line 664, in connect
    raise exc
pymysql.err.OperationalError: (2003, "Can't connect to MySQL server on 'backendqa0001.globo.correio.biz' (timed out)")

2021-08-09 20:41:12,935 - ERROR - An Error occurred while handling migrations: Traceback (most recent call last):
  File "/usr/local/lib/python3.8/site-packages/pymysql/connections.py", line 613, in connect
    sock = socket.create_connection(
  File "/usr/local/lib/python3.8/socket.py", line 808, in create_connection
    raise err
  File "/usr/local/lib/python3.8/socket.py", line 796, in create_connection
    sock.connect(sa)
socket.timeout: timed out

During handling of the above exception, another exception occurred:

Traceback (most recent call last):
  File "main.py", line 25, in handler_service
    handler_migration = IntegratorService(logger)
  File "/opt/globo/integrator/service.py", line 20, in __init__
    self.globomail_repository = GlobomailRepository()
  File "/opt/globo/repositories/globomail.py", line 12, in __init__
    self.connection = pymysql.connect(host=self.hostname, user=self.username, password=self.password,
  File "/usr/local/lib/python3.8/site-packages/pymysql/connections.py", line 353, in __init__
    self.connect()
  File "/usr/local/lib/python3.8/site-packages/pymysql/connections.py", line 664, in connect
    raise exc
pymysql.err.OperationalError: (2003, "Can't connect to MySQL server on 'backendqa0001.globo.correio.biz' (timed out)")

2021-08-09 20:44:47,069 - ERROR - An Error occurred while handling migrations: Traceback (most recent call last):
  File "/usr/local/lib/python3.8/site-packages/pymysql/connections.py", line 613, in connect
    sock = socket.create_connection(
  File "/usr/local/lib/python3.8/socket.py", line 808, in create_connection
    raise err
  File "/usr/local/lib/python3.8/socket.py", line 796, in create_connection
    sock.connect(sa)
socket.timeout: timed out

During handling of the above exception, another exception occurred:

Traceback (most recent call last):
  File "main.py", line 25, in handler_service
    handler_migration = IntegratorService(logger)
  File "/opt/globo/integrator/service.py", line 20, in __init__
    self.globomail_repository = GlobomailRepository()
  File "/opt/globo/repositories/globomail.py", line 12, in __init__
    self.connection = pymysql.connect(host=self.hostname, user=self.username, password=self.password,
  File "/usr/local/lib/python3.8/site-packages/pymysql/connections.py", line 353, in __init__
    self.connect()
  File "/usr/local/lib/python3.8/site-packages/pymysql/connections.py", line 664, in connect
    raise exc
pymysql.err.OperationalError: (2003, "Can't connect to MySQL server on 'backendqa0001.globo.correio.biz' (timed out)")

2021-08-09 20:45:57,392 - ERROR - An Error occurred while handling migrations: Traceback (most recent call last):
  File "/usr/local/lib/python3.8/site-packages/pymysql/connections.py", line 613, in connect
    sock = socket.create_connection(
  File "/usr/local/lib/python3.8/socket.py", line 808, in create_connection
    raise err
  File "/usr/local/lib/python3.8/socket.py", line 796, in create_connection
    sock.connect(sa)
socket.timeout: timed out

During handling of the above exception, another exception occurred:

Traceback (most recent call last):
  File "main.py", line 25, in handler_service
    handler_migration = IntegratorService(logger)
  File "/opt/globo/integrator/service.py", line 20, in __init__
    self.globomail_repository = GlobomailRepository()
  File "/opt/globo/repositories/globomail.py", line 12, in __init__
    self.connection = pymysql.connect(host=self.hostname, user=self.username, password=self.password,
  File "/usr/local/lib/python3.8/site-packages/pymysql/connections.py", line 353, in __init__
    self.connect()
  File "/usr/local/lib/python3.8/site-packages/pymysql/connections.py", line 664, in connect
    raise exc
pymysql.err.OperationalError: (2003, "Can't connect to MySQL server on 'backendqa0001.globo.correio.biz' (timed out)")

2021-08-09 20:47:07,714 - ERROR - An Error occurred while handling migrations: Traceback (most recent call last):
  File "/usr/local/lib/python3.8/site-packages/pymysql/connections.py", line 613, in connect
    sock = socket.create_connection(
  File "/usr/local/lib/python3.8/socket.py", line 808, in create_connection
    raise err
  File "/usr/local/lib/python3.8/socket.py", line 796, in create_connection
    sock.connect(sa)
socket.timeout: timed out

During handling of the above exception, another exception occurred:

Traceback (most recent call last):
  File "main.py", line 25, in handler_service
    handler_migration = IntegratorService(logger)
  File "/opt/globo/integrator/service.py", line 20, in __init__
    self.globomail_repository = GlobomailRepository()
  File "/opt/globo/repositories/globomail.py", line 12, in __init__
    self.connection = pymysql.connect(host=self.hostname, user=self.username, password=self.password,
  File "/usr/local/lib/python3.8/site-packages/pymysql/connections.py", line 353, in __init__
    self.connect()
  File "/usr/local/lib/python3.8/site-packages/pymysql/connections.py", line 664, in connect
    raise exc
pymysql.err.OperationalError: (2003, "Can't connect to MySQL server on 'backendqa0001.globo.correio.biz' (timed out)")

2021-08-09 20:48:18,094 - ERROR - An Error occurred while handling migrations: Traceback (most recent call last):
  File "/usr/local/lib/python3.8/site-packages/pymysql/connections.py", line 613, in connect
    sock = socket.create_connection(
  File "/usr/local/lib/python3.8/socket.py", line 808, in create_connection
    raise err
  File "/usr/local/lib/python3.8/socket.py", line 796, in create_connection
    sock.connect(sa)
socket.timeout: timed out

During handling of the above exception, another exception occurred:

Traceback (most recent call last):
  File "main.py", line 25, in handler_service
    handler_migration = IntegratorService(logger)
  File "/opt/globo/integrator/service.py", line 20, in __init__
    self.globomail_repository = GlobomailRepository()
  File "/opt/globo/repositories/globomail.py", line 12, in __init__
    self.connection = pymysql.connect(host=self.hostname, user=self.username, password=self.password,
  File "/usr/local/lib/python3.8/site-packages/pymysql/connections.py", line 353, in __init__
    self.connect()
  File "/usr/local/lib/python3.8/site-packages/pymysql/connections.py", line 664, in connect
    raise exc
pymysql.err.OperationalError: (2003, "Can't connect to MySQL server on 'backendqa0001.globo.correio.biz' (timed out)")

2021-08-09 20:49:28,484 - ERROR - An Error occurred while handling migrations: Traceback (most recent call last):
  File "/usr/local/lib/python3.8/site-packages/pymysql/connections.py", line 613, in connect
    sock = socket.create_connection(
  File "/usr/local/lib/python3.8/socket.py", line 808, in create_connection
    raise err
  File "/usr/local/lib/python3.8/socket.py", line 796, in create_connection
    sock.connect(sa)
socket.timeout: timed out

During handling of the above exception, another exception occurred:

Traceback (most recent call last):
  File "main.py", line 25, in handler_service
    handler_migration = IntegratorService(logger)
  File "/opt/globo/integrator/service.py", line 20, in __init__
    self.globomail_repository = GlobomailRepository()
  File "/opt/globo/repositories/globomail.py", line 12, in __init__
    self.connection = pymysql.connect(host=self.hostname, user=self.username, password=self.password,
  File "/usr/local/lib/python3.8/site-packages/pymysql/connections.py", line 353, in __init__
    self.connect()
  File "/usr/local/lib/python3.8/site-packages/pymysql/connections.py", line 664, in connect
    raise exc
pymysql.err.OperationalError: (2003, "Can't connect to MySQL server on 'backendqa0001.globo.correio.biz' (timed out)")

2021-08-09 20:50:38,778 - ERROR - An Error occurred while handling migrations: Traceback (most recent call last):
  File "/usr/local/lib/python3.8/site-packages/pymysql/connections.py", line 613, in connect
    sock = socket.create_connection(
  File "/usr/local/lib/python3.8/socket.py", line 808, in create_connection
    raise err
  File "/usr/local/lib/python3.8/socket.py", line 796, in create_connection
    sock.connect(sa)
socket.timeout: timed out

During handling of the above exception, another exception occurred:

Traceback (most recent call last):
  File "main.py", line 25, in handler_service
    handler_migration = IntegratorService(logger)
  File "/opt/globo/integrator/service.py", line 20, in __init__
    self.globomail_repository = GlobomailRepository()
  File "/opt/globo/repositories/globomail.py", line 12, in __init__
    self.connection = pymysql.connect(host=self.hostname, user=self.username, password=self.password,
  File "/usr/local/lib/python3.8/site-packages/pymysql/connections.py", line 353, in __init__
    self.connect()
  File "/usr/local/lib/python3.8/site-packages/pymysql/connections.py", line 664, in connect
    raise exc
pymysql.err.OperationalError: (2003, "Can't connect to MySQL server on 'backendqa0001.globo.correio.biz' (timed out)")

2021-08-09 20:51:49,130 - ERROR - An Error occurred while handling migrations: Traceback (most recent call last):
  File "/usr/local/lib/python3.8/site-packages/pymysql/connections.py", line 613, in connect
    sock = socket.create_connection(
  File "/usr/local/lib/python3.8/socket.py", line 808, in create_connection
    raise err
  File "/usr/local/lib/python3.8/socket.py", line 796, in create_connection
    sock.connect(sa)
socket.timeout: timed out

During handling of the above exception, another exception occurred:

Traceback (most recent call last):
  File "main.py", line 25, in handler_service
    handler_migration = IntegratorService(logger)
  File "/opt/globo/integrator/service.py", line 20, in __init__
    self.globomail_repository = GlobomailRepository()
  File "/opt/globo/repositories/globomail.py", line 12, in __init__
    self.connection = pymysql.connect(host=self.hostname, user=self.username, password=self.password,
  File "/usr/local/lib/python3.8/site-packages/pymysql/connections.py", line 353, in __init__
    self.connect()
  File "/usr/local/lib/python3.8/site-packages/pymysql/connections.py", line 664, in connect
    raise exc
pymysql.err.OperationalError: (2003, "Can't connect to MySQL server on 'backendqa0001.globo.correio.biz' (timed out)")

2021-08-09 20:52:59,431 - ERROR - An Error occurred while handling migrations: Traceback (most recent call last):
  File "/usr/local/lib/python3.8/site-packages/pymysql/connections.py", line 613, in connect
    sock = socket.create_connection(
  File "/usr/local/lib/python3.8/socket.py", line 808, in create_connection
    raise err
  File "/usr/local/lib/python3.8/socket.py", line 796, in create_connection
    sock.connect(sa)
socket.timeout: timed out

During handling of the above exception, another exception occurred:

Traceback (most recent call last):
  File "main.py", line 25, in handler_service
    handler_migration = IntegratorService(logger)
  File "/opt/globo/integrator/service.py", line 20, in __init__
    self.globomail_repository = GlobomailRepository()
  File "/opt/globo/repositories/globomail.py", line 12, in __init__
    self.connection = pymysql.connect(host=self.hostname, user=self.username, password=self.password,
  File "/usr/local/lib/python3.8/site-packages/pymysql/connections.py", line 353, in __init__
    self.connect()
  File "/usr/local/lib/python3.8/site-packages/pymysql/connections.py", line 664, in connect
    raise exc
pymysql.err.OperationalError: (2003, "Can't connect to MySQL server on 'backendqa0001.globo.correio.biz' (timed out)")

2021-08-09 20:54:09,743 - ERROR - An Error occurred while handling migrations: Traceback (most recent call last):
  File "/usr/local/lib/python3.8/site-packages/pymysql/connections.py", line 613, in connect
    sock = socket.create_connection(
  File "/usr/local/lib/python3.8/socket.py", line 808, in create_connection
    raise err
  File "/usr/local/lib/python3.8/socket.py", line 796, in create_connection
    sock.connect(sa)
socket.timeout: timed out

During handling of the above exception, another exception occurred:

Traceback (most recent call last):
  File "main.py", line 25, in handler_service
    handler_migration = IntegratorService(logger)
  File "/opt/globo/integrator/service.py", line 20, in __init__
    self.globomail_repository = GlobomailRepository()
  File "/opt/globo/repositories/globomail.py", line 12, in __init__
    self.connection = pymysql.connect(host=self.hostname, user=self.username, password=self.password,
  File "/usr/local/lib/python3.8/site-packages/pymysql/connections.py", line 353, in __init__
    self.connect()
  File "/usr/local/lib/python3.8/site-packages/pymysql/connections.py", line 664, in connect
    raise exc
pymysql.err.OperationalError: (2003, "Can't connect to MySQL server on 'backendqa0001.globo.correio.biz' (timed out)")

2021-08-09 20:55:20,047 - ERROR - An Error occurred while handling migrations: Traceback (most recent call last):
  File "/usr/local/lib/python3.8/site-packages/pymysql/connections.py", line 613, in connect
    sock = socket.create_connection(
  File "/usr/local/lib/python3.8/socket.py", line 808, in create_connection
    raise err
  File "/usr/local/lib/python3.8/socket.py", line 796, in create_connection
    sock.connect(sa)
socket.timeout: timed out

During handling of the above exception, another exception occurred:

Traceback (most recent call last):
  File "main.py", line 25, in handler_service
    handler_migration = IntegratorService(logger)
  File "/opt/globo/integrator/service.py", line 20, in __init__
    self.globomail_repository = GlobomailRepository()
  File "/opt/globo/repositories/globomail.py", line 12, in __init__
    self.connection = pymysql.connect(host=self.hostname, user=self.username, password=self.password,
  File "/usr/local/lib/python3.8/site-packages/pymysql/connections.py", line 353, in __init__
    self.connect()
  File "/usr/local/lib/python3.8/site-packages/pymysql/connections.py", line 664, in connect
    raise exc
pymysql.err.OperationalError: (2003, "Can't connect to MySQL server on 'backendqa0001.globo.correio.biz' (timed out)")

2021-08-09 20:56:30,418 - ERROR - An Error occurred while handling migrations: Traceback (most recent call last):
  File "/usr/local/lib/python3.8/site-packages/pymysql/connections.py", line 613, in connect
    sock = socket.create_connection(
  File "/usr/local/lib/python3.8/socket.py", line 808, in create_connection
    raise err
  File "/usr/local/lib/python3.8/socket.py", line 796, in create_connection
    sock.connect(sa)
socket.timeout: timed out

During handling of the above exception, another exception occurred:

Traceback (most recent call last):
  File "main.py", line 25, in handler_service
    handler_migration = IntegratorService(logger)
  File "/opt/globo/integrator/service.py", line 20, in __init__
    self.globomail_repository = GlobomailRepository()
  File "/opt/globo/repositories/globomail.py", line 12, in __init__
    self.connection = pymysql.connect(host=self.hostname, user=self.username, password=self.password,
  File "/usr/local/lib/python3.8/site-packages/pymysql/connections.py", line 353, in __init__
    self.connect()
  File "/usr/local/lib/python3.8/site-packages/pymysql/connections.py", line 664, in connect
    raise exc
pymysql.err.OperationalError: (2003, "Can't connect to MySQL server on 'backendqa0001.globo.correio.biz' (timed out)")

2021-08-09 20:57:40,769 - ERROR - An Error occurred while handling migrations: Traceback (most recent call last):
  File "/usr/local/lib/python3.8/site-packages/pymysql/connections.py", line 613, in connect
    sock = socket.create_connection(
  File "/usr/local/lib/python3.8/socket.py", line 808, in create_connection
    raise err
  File "/usr/local/lib/python3.8/socket.py", line 796, in create_connection
    sock.connect(sa)
socket.timeout: timed out

During handling of the above exception, another exception occurred:

Traceback (most recent call last):
  File "main.py", line 25, in handler_service
    handler_migration = IntegratorService(logger)
  File "/opt/globo/integrator/service.py", line 20, in __init__
    self.globomail_repository = GlobomailRepository()
  File "/opt/globo/repositories/globomail.py", line 12, in __init__
    self.connection = pymysql.connect(host=self.hostname, user=self.username, password=self.password,
  File "/usr/local/lib/python3.8/site-packages/pymysql/connections.py", line 353, in __init__
    self.connect()
  File "/usr/local/lib/python3.8/site-packages/pymysql/connections.py", line 664, in connect
    raise exc
pymysql.err.OperationalError: (2003, "Can't connect to MySQL server on 'backendqa0001.globo.correio.biz' (timed out)")

2021-08-09 20:58:51,089 - ERROR - An Error occurred while handling migrations: Traceback (most recent call last):
  File "/usr/local/lib/python3.8/site-packages/pymysql/connections.py", line 613, in connect
    sock = socket.create_connection(
  File "/usr/local/lib/python3.8/socket.py", line 808, in create_connection
    raise err
  File "/usr/local/lib/python3.8/socket.py", line 796, in create_connection
    sock.connect(sa)
socket.timeout: timed out

During handling of the above exception, another exception occurred:

Traceback (most recent call last):
  File "main.py", line 25, in handler_service
    handler_migration = IntegratorService(logger)
  File "/opt/globo/integrator/service.py", line 20, in __init__
    self.globomail_repository = GlobomailRepository()
  File "/opt/globo/repositories/globomail.py", line 12, in __init__
    self.connection = pymysql.connect(host=self.hostname, user=self.username, password=self.password,
  File "/usr/local/lib/python3.8/site-packages/pymysql/connections.py", line 353, in __init__
    self.connect()
  File "/usr/local/lib/python3.8/site-packages/pymysql/connections.py", line 664, in connect
    raise exc
pymysql.err.OperationalError: (2003, "Can't connect to MySQL server on 'backendqa0001.globo.correio.biz' (timed out)")

2021-08-09 21:00:01,498 - ERROR - An Error occurred while handling migrations: Traceback (most recent call last):
  File "/usr/local/lib/python3.8/site-packages/pymysql/connections.py", line 613, in connect
    sock = socket.create_connection(
  File "/usr/local/lib/python3.8/socket.py", line 808, in create_connection
    raise err
  File "/usr/local/lib/python3.8/socket.py", line 796, in create_connection
    sock.connect(sa)
socket.timeout: timed out

During handling of the above exception, another exception occurred:

Traceback (most recent call last):
  File "main.py", line 25, in handler_service
    handler_migration = IntegratorService(logger)
  File "/opt/globo/integrator/service.py", line 20, in __init__
    self.globomail_repository = GlobomailRepository()
  File "/opt/globo/repositories/globomail.py", line 12, in __init__
    self.connection = pymysql.connect(host=self.hostname, user=self.username, password=self.password,
  File "/usr/local/lib/python3.8/site-packages/pymysql/connections.py", line 353, in __init__
    self.connect()
  File "/usr/local/lib/python3.8/site-packages/pymysql/connections.py", line 664, in connect
    raise exc
pymysql.err.OperationalError: (2003, "Can't connect to MySQL server on 'backendqa0001.globo.correio.biz' (timed out)")

2021-08-09 21:15:18,876 - ERROR - An Error occurred while handling migrations: Traceback (most recent call last):
  File "/usr/local/lib/python3.8/site-packages/pymysql/connections.py", line 613, in connect
    sock = socket.create_connection(
  File "/usr/local/lib/python3.8/socket.py", line 808, in create_connection
    raise err
  File "/usr/local/lib/python3.8/socket.py", line 796, in create_connection
    sock.connect(sa)
socket.timeout: timed out

During handling of the above exception, another exception occurred:

Traceback (most recent call last):
  File "main.py", line 25, in handler_service
    handler_migration = IntegratorService(logger)
  File "/opt/globo/integrator/service.py", line 20, in __init__
    self.globomail_repository = GlobomailRepository()
  File "/opt/globo/repositories/globomail.py", line 12, in __init__
    self.connection = pymysql.connect(host=self.hostname, user=self.username, password=self.password,
  File "/usr/local/lib/python3.8/site-packages/pymysql/connections.py", line 353, in __init__
    self.connect()
  File "/usr/local/lib/python3.8/site-packages/pymysql/connections.py", line 664, in connect
    raise exc
pymysql.err.OperationalError: (2003, "Can't connect to MySQL server on 'backendqa0001.globo.correio.biz' (timed out)")

2021-08-09 21:16:29,216 - ERROR - An Error occurred while handling migrations: Traceback (most recent call last):
  File "/usr/local/lib/python3.8/site-packages/pymysql/connections.py", line 613, in connect
    sock = socket.create_connection(
  File "/usr/local/lib/python3.8/socket.py", line 808, in create_connection
    raise err
  File "/usr/local/lib/python3.8/socket.py", line 796, in create_connection
    sock.connect(sa)
socket.timeout: timed out

During handling of the above exception, another exception occurred:

Traceback (most recent call last):
  File "main.py", line 25, in handler_service
    handler_migration = IntegratorService(logger)
  File "/opt/globo/integrator/service.py", line 20, in __init__
    self.globomail_repository = GlobomailRepository()
  File "/opt/globo/repositories/globomail.py", line 12, in __init__
    self.connection = pymysql.connect(host=self.hostname, user=self.username, password=self.password,
  File "/usr/local/lib/python3.8/site-packages/pymysql/connections.py", line 353, in __init__
    self.connect()
  File "/usr/local/lib/python3.8/site-packages/pymysql/connections.py", line 664, in connect
    raise exc
pymysql.err.OperationalError: (2003, "Can't connect to MySQL server on 'backendqa0001.globo.correio.biz' (timed out)")

2021-08-09 21:17:39,541 - ERROR - An Error occurred while handling migrations: Traceback (most recent call last):
  File "/usr/local/lib/python3.8/site-packages/pymysql/connections.py", line 613, in connect
    sock = socket.create_connection(
  File "/usr/local/lib/python3.8/socket.py", line 808, in create_connection
    raise err
  File "/usr/local/lib/python3.8/socket.py", line 796, in create_connection
    sock.connect(sa)
socket.timeout: timed out

During handling of the above exception, another exception occurred:

Traceback (most recent call last):
  File "main.py", line 25, in handler_service
    handler_migration = IntegratorService(logger)
  File "/opt/globo/integrator/service.py", line 20, in __init__
    self.globomail_repository = GlobomailRepository()
  File "/opt/globo/repositories/globomail.py", line 12, in __init__
    self.connection = pymysql.connect(host=self.hostname, user=self.username, password=self.password,
  File "/usr/local/lib/python3.8/site-packages/pymysql/connections.py", line 353, in __init__
    self.connect()
  File "/usr/local/lib/python3.8/site-packages/pymysql/connections.py", line 664, in connect
    raise exc
pymysql.err.OperationalError: (2003, "Can't connect to MySQL server on 'backendqa0001.globo.correio.biz' (timed out)")

2021-08-09 21:18:49,883 - ERROR - An Error occurred while handling migrations: Traceback (most recent call last):
  File "/usr/local/lib/python3.8/site-packages/pymysql/connections.py", line 613, in connect
    sock = socket.create_connection(
  File "/usr/local/lib/python3.8/socket.py", line 808, in create_connection
    raise err
  File "/usr/local/lib/python3.8/socket.py", line 796, in create_connection
    sock.connect(sa)
socket.timeout: timed out

During handling of the above exception, another exception occurred:

Traceback (most recent call last):
  File "main.py", line 25, in handler_service
    handler_migration = IntegratorService(logger)
  File "/opt/globo/integrator/service.py", line 20, in __init__
    self.globomail_repository = GlobomailRepository()
  File "/opt/globo/repositories/globomail.py", line 12, in __init__
    self.connection = pymysql.connect(host=self.hostname, user=self.username, password=self.password,
  File "/usr/local/lib/python3.8/site-packages/pymysql/connections.py", line 353, in __init__
    self.connect()
  File "/usr/local/lib/python3.8/site-packages/pymysql/connections.py", line 664, in connect
    raise exc
pymysql.err.OperationalError: (2003, "Can't connect to MySQL server on 'backendqa0001.globo.correio.biz' (timed out)")

2021-08-09 21:20:00,246 - ERROR - An Error occurred while handling migrations: Traceback (most recent call last):
  File "/usr/local/lib/python3.8/site-packages/pymysql/connections.py", line 613, in connect
    sock = socket.create_connection(
  File "/usr/local/lib/python3.8/socket.py", line 808, in create_connection
    raise err
  File "/usr/local/lib/python3.8/socket.py", line 796, in create_connection
    sock.connect(sa)
socket.timeout: timed out

During handling of the above exception, another exception occurred:

Traceback (most recent call last):
  File "main.py", line 25, in handler_service
    handler_migration = IntegratorService(logger)
  File "/opt/globo/integrator/service.py", line 20, in __init__
    self.globomail_repository = GlobomailRepository()
  File "/opt/globo/repositories/globomail.py", line 12, in __init__
    self.connection = pymysql.connect(host=self.hostname, user=self.username, password=self.password,
  File "/usr/local/lib/python3.8/site-packages/pymysql/connections.py", line 353, in __init__
    self.connect()
  File "/usr/local/lib/python3.8/site-packages/pymysql/connections.py", line 664, in connect
    raise exc
pymysql.err.OperationalError: (2003, "Can't connect to MySQL server on 'backendqa0001.globo.correio.biz' (timed out)")

2021-08-09 21:21:10,611 - ERROR - An Error occurred while handling migrations: Traceback (most recent call last):
  File "/usr/local/lib/python3.8/site-packages/pymysql/connections.py", line 613, in connect
    sock = socket.create_connection(
  File "/usr/local/lib/python3.8/socket.py", line 808, in create_connection
    raise err
  File "/usr/local/lib/python3.8/socket.py", line 796, in create_connection
    sock.connect(sa)
socket.timeout: timed out

During handling of the above exception, another exception occurred:

Traceback (most recent call last):
  File "main.py", line 25, in handler_service
    handler_migration = IntegratorService(logger)
  File "/opt/globo/integrator/service.py", line 20, in __init__
    self.globomail_repository = GlobomailRepository()
  File "/opt/globo/repositories/globomail.py", line 12, in __init__
    self.connection = pymysql.connect(host=self.hostname, user=self.username, password=self.password,
  File "/usr/local/lib/python3.8/site-packages/pymysql/connections.py", line 353, in __init__
    self.connect()
  File "/usr/local/lib/python3.8/site-packages/pymysql/connections.py", line 664, in connect
    raise exc
pymysql.err.OperationalError: (2003, "Can't connect to MySQL server on 'backendqa0001.globo.correio.biz' (timed out)")

2021-08-09 21:22:20,951 - ERROR - An Error occurred while handling migrations: Traceback (most recent call last):
  File "/usr/local/lib/python3.8/site-packages/pymysql/connections.py", line 613, in connect
    sock = socket.create_connection(
  File "/usr/local/lib/python3.8/socket.py", line 808, in create_connection
    raise err
  File "/usr/local/lib/python3.8/socket.py", line 796, in create_connection
    sock.connect(sa)
socket.timeout: timed out

During handling of the above exception, another exception occurred:

Traceback (most recent call last):
  File "main.py", line 25, in handler_service
    handler_migration = IntegratorService(logger)
  File "/opt/globo/integrator/service.py", line 20, in __init__
    self.globomail_repository = GlobomailRepository()
  File "/opt/globo/repositories/globomail.py", line 12, in __init__
    self.connection = pymysql.connect(host=self.hostname, user=self.username, password=self.password,
  File "/usr/local/lib/python3.8/site-packages/pymysql/connections.py", line 353, in __init__
    self.connect()
  File "/usr/local/lib/python3.8/site-packages/pymysql/connections.py", line 664, in connect
    raise exc
pymysql.err.OperationalError: (2003, "Can't connect to MySQL server on 'backendqa0001.globo.correio.biz' (timed out)")

2021-08-09 21:23:31,304 - ERROR - An Error occurred while handling migrations: Traceback (most recent call last):
  File "/usr/local/lib/python3.8/site-packages/pymysql/connections.py", line 613, in connect
    sock = socket.create_connection(
  File "/usr/local/lib/python3.8/socket.py", line 808, in create_connection
    raise err
  File "/usr/local/lib/python3.8/socket.py", line 796, in create_connection
    sock.connect(sa)
socket.timeout: timed out

During handling of the above exception, another exception occurred:

Traceback (most recent call last):
  File "main.py", line 25, in handler_service
    handler_migration = IntegratorService(logger)
  File "/opt/globo/integrator/service.py", line 20, in __init__
    self.globomail_repository = GlobomailRepository()
  File "/opt/globo/repositories/globomail.py", line 12, in __init__
    self.connection = pymysql.connect(host=self.hostname, user=self.username, password=self.password,
  File "/usr/local/lib/python3.8/site-packages/pymysql/connections.py", line 353, in __init__
    self.connect()
  File "/usr/local/lib/python3.8/site-packages/pymysql/connections.py", line 664, in connect
    raise exc
pymysql.err.OperationalError: (2003, "Can't connect to MySQL server on 'backendqa0001.globo.correio.biz' (timed out)")

2021-08-09 21:24:41,641 - ERROR - An Error occurred while handling migrations: Traceback (most recent call last):
  File "/usr/local/lib/python3.8/site-packages/pymysql/connections.py", line 613, in connect
    sock = socket.create_connection(
  File "/usr/local/lib/python3.8/socket.py", line 808, in create_connection
    raise err
  File "/usr/local/lib/python3.8/socket.py", line 796, in create_connection
    sock.connect(sa)
socket.timeout: timed out

During handling of the above exception, another exception occurred:

Traceback (most recent call last):
  File "main.py", line 25, in handler_service
    handler_migration = IntegratorService(logger)
  File "/opt/globo/integrator/service.py", line 20, in __init__
    self.globomail_repository = GlobomailRepository()
  File "/opt/globo/repositories/globomail.py", line 12, in __init__
    self.connection = pymysql.connect(host=self.hostname, user=self.username, password=self.password,
  File "/usr/local/lib/python3.8/site-packages/pymysql/connections.py", line 353, in __init__
    self.connect()
  File "/usr/local/lib/python3.8/site-packages/pymysql/connections.py", line 664, in connect
    raise exc
pymysql.err.OperationalError: (2003, "Can't connect to MySQL server on 'backendqa0001.globo.correio.biz' (timed out)")

2021-08-09 21:25:52,010 - ERROR - An Error occurred while handling migrations: Traceback (most recent call last):
  File "/usr/local/lib/python3.8/site-packages/pymysql/connections.py", line 613, in connect
    sock = socket.create_connection(
  File "/usr/local/lib/python3.8/socket.py", line 808, in create_connection
    raise err
  File "/usr/local/lib/python3.8/socket.py", line 796, in create_connection
    sock.connect(sa)
socket.timeout: timed out

During handling of the above exception, another exception occurred:

Traceback (most recent call last):
  File "main.py", line 25, in handler_service
    handler_migration = IntegratorService(logger)
  File "/opt/globo/integrator/service.py", line 20, in __init__
    self.globomail_repository = GlobomailRepository()
  File "/opt/globo/repositories/globomail.py", line 12, in __init__
    self.connection = pymysql.connect(host=self.hostname, user=self.username, password=self.password,
  File "/usr/local/lib/python3.8/site-packages/pymysql/connections.py", line 353, in __init__
    self.connect()
  File "/usr/local/lib/python3.8/site-packages/pymysql/connections.py", line 664, in connect
    raise exc
pymysql.err.OperationalError: (2003, "Can't connect to MySQL server on 'backendqa0001.globo.correio.biz' (timed out)")

2021-08-09 21:27:02,378 - ERROR - An Error occurred while handling migrations: Traceback (most recent call last):
  File "/usr/local/lib/python3.8/site-packages/pymysql/connections.py", line 613, in connect
    sock = socket.create_connection(
  File "/usr/local/lib/python3.8/socket.py", line 808, in create_connection
    raise err
  File "/usr/local/lib/python3.8/socket.py", line 796, in create_connection
    sock.connect(sa)
socket.timeout: timed out

During handling of the above exception, another exception occurred:

Traceback (most recent call last):
  File "main.py", line 25, in handler_service
    handler_migration = IntegratorService(logger)
  File "/opt/globo/integrator/service.py", line 20, in __init__
    self.globomail_repository = GlobomailRepository()
  File "/opt/globo/repositories/globomail.py", line 12, in __init__
    self.connection = pymysql.connect(host=self.hostname, user=self.username, password=self.password,
  File "/usr/local/lib/python3.8/site-packages/pymysql/connections.py", line 353, in __init__
    self.connect()
  File "/usr/local/lib/python3.8/site-packages/pymysql/connections.py", line 664, in connect
    raise exc
pymysql.err.OperationalError: (2003, "Can't connect to MySQL server on 'backendqa0001.globo.correio.biz' (timed out)")

2021-08-09 21:28:12,744 - ERROR - An Error occurred while handling migrations: Traceback (most recent call last):
  File "/usr/local/lib/python3.8/site-packages/pymysql/connections.py", line 613, in connect
    sock = socket.create_connection(
  File "/usr/local/lib/python3.8/socket.py", line 808, in create_connection
    raise err
  File "/usr/local/lib/python3.8/socket.py", line 796, in create_connection
    sock.connect(sa)
socket.timeout: timed out

During handling of the above exception, another exception occurred:

Traceback (most recent call last):
  File "main.py", line 25, in handler_service
    handler_migration = IntegratorService(logger)
  File "/opt/globo/integrator/service.py", line 20, in __init__
    self.globomail_repository = GlobomailRepository()
  File "/opt/globo/repositories/globomail.py", line 12, in __init__
    self.connection = pymysql.connect(host=self.hostname, user=self.username, password=self.password,
  File "/usr/local/lib/python3.8/site-packages/pymysql/connections.py", line 353, in __init__
    self.connect()
  File "/usr/local/lib/python3.8/site-packages/pymysql/connections.py", line 664, in connect
    raise exc
pymysql.err.OperationalError: (2003, "Can't connect to MySQL server on 'backendqa0001.globo.correio.biz' (timed out)")

2021-08-09 21:29:23,086 - ERROR - An Error occurred while handling migrations: Traceback (most recent call last):
  File "/usr/local/lib/python3.8/site-packages/pymysql/connections.py", line 613, in connect
    sock = socket.create_connection(
  File "/usr/local/lib/python3.8/socket.py", line 808, in create_connection
    raise err
  File "/usr/local/lib/python3.8/socket.py", line 796, in create_connection
    sock.connect(sa)
socket.timeout: timed out

During handling of the above exception, another exception occurred:

Traceback (most recent call last):
  File "main.py", line 25, in handler_service
    handler_migration = IntegratorService(logger)
  File "/opt/globo/integrator/service.py", line 20, in __init__
    self.globomail_repository = GlobomailRepository()
  File "/opt/globo/repositories/globomail.py", line 12, in __init__
    self.connection = pymysql.connect(host=self.hostname, user=self.username, password=self.password,
  File "/usr/local/lib/python3.8/site-packages/pymysql/connections.py", line 353, in __init__
    self.connect()
  File "/usr/local/lib/python3.8/site-packages/pymysql/connections.py", line 664, in connect
    raise exc
pymysql.err.OperationalError: (2003, "Can't connect to MySQL server on 'backendqa0001.globo.correio.biz' (timed out)")

2021-08-09 22:34:40,641 - ERROR - An Error occurred while handling migrations: Traceback (most recent call last):
  File "/usr/local/lib/python3.8/site-packages/pymysql/connections.py", line 613, in connect
    sock = socket.create_connection(
  File "/usr/local/lib/python3.8/socket.py", line 808, in create_connection
    raise err
  File "/usr/local/lib/python3.8/socket.py", line 796, in create_connection
    sock.connect(sa)
socket.timeout: timed out

During handling of the above exception, another exception occurred:

Traceback (most recent call last):
  File "main.py", line 25, in handler_service
    handler_migration = IntegratorService(logger)
  File "/opt/globo/integrator/service.py", line 20, in __init__
    self.globomail_repository = GlobomailRepository()
  File "/opt/globo/repositories/globomail.py", line 12, in __init__
    self.connection = pymysql.connect(host=self.hostname, user=self.username, password=self.password,
  File "/usr/local/lib/python3.8/site-packages/pymysql/connections.py", line 353, in __init__
    self.connect()
  File "/usr/local/lib/python3.8/site-packages/pymysql/connections.py", line 664, in connect
    raise exc
pymysql.err.OperationalError: (2003, "Can't connect to MySQL server on 'backendqa0001.globo.correio.biz' (timed out)")

2021-08-09 23:39:32,841 - ERROR - An Error occurred while handling migrations: Traceback (most recent call last):
  File "/usr/local/lib/python3.8/site-packages/pymysql/connections.py", line 613, in connect
    sock = socket.create_connection(
  File "/usr/local/lib/python3.8/socket.py", line 808, in create_connection
    raise err
  File "/usr/local/lib/python3.8/socket.py", line 796, in create_connection
    sock.connect(sa)
socket.timeout: timed out

During handling of the above exception, another exception occurred:

Traceback (most recent call last):
  File "main.py", line 25, in handler_service
    handler_migration = IntegratorService(logger)
  File "/opt/globo/integrator/service.py", line 20, in __init__
    self.globomail_repository = GlobomailRepository()
  File "/opt/globo/repositories/globomail.py", line 12, in __init__
    self.connection = pymysql.connect(host=self.hostname, user=self.username, password=self.password,
  File "/usr/local/lib/python3.8/site-packages/pymysql/connections.py", line 353, in __init__
    self.connect()
  File "/usr/local/lib/python3.8/site-packages/pymysql/connections.py", line 664, in connect
    raise exc
pymysql.err.OperationalError: (2003, "Can't connect to MySQL server on 'backendqa0001.globo.correio.biz' (timed out)")

2021-08-10 00:30:57,768 - ERROR - An Error occurred while handling migrations: Traceback (most recent call last):
  File "/usr/local/lib/python3.8/site-packages/pymysql/connections.py", line 613, in connect
    sock = socket.create_connection(
  File "/usr/local/lib/python3.8/socket.py", line 808, in create_connection
    raise err
  File "/usr/local/lib/python3.8/socket.py", line 796, in create_connection
    sock.connect(sa)
socket.timeout: timed out

During handling of the above exception, another exception occurred:

Traceback (most recent call last):
  File "main.py", line 25, in handler_service
    handler_migration = IntegratorService(logger)
  File "/opt/globo/integrator/service.py", line 20, in __init__
    self.globomail_repository = GlobomailRepository()
  File "/opt/globo/repositories/globomail.py", line 12, in __init__
    self.connection = pymysql.connect(host=self.hostname, user=self.username, password=self.password,
  File "/usr/local/lib/python3.8/site-packages/pymysql/connections.py", line 353, in __init__
    self.connect()
  File "/usr/local/lib/python3.8/site-packages/pymysql/connections.py", line 664, in connect
    raise exc
pymysql.err.OperationalError: (2003, "Can't connect to MySQL server on 'backendqa0001.globo.correio.biz' (timed out)")

2021-08-10 00:32:25,213 - ERROR - An Error occurred while handling migrations: Traceback (most recent call last):
  File "/usr/local/lib/python3.8/site-packages/pymysql/connections.py", line 613, in connect
    sock = socket.create_connection(
  File "/usr/local/lib/python3.8/socket.py", line 808, in create_connection
    raise err
  File "/usr/local/lib/python3.8/socket.py", line 796, in create_connection
    sock.connect(sa)
socket.timeout: timed out

During handling of the above exception, another exception occurred:

Traceback (most recent call last):
  File "main.py", line 25, in handler_service
    handler_migration = IntegratorService(logger)
  File "/opt/globo/integrator/service.py", line 20, in __init__
    self.globomail_repository = GlobomailRepository()
  File "/opt/globo/repositories/globomail.py", line 12, in __init__
    self.connection = pymysql.connect(host=self.hostname, user=self.username, password=self.password,
  File "/usr/local/lib/python3.8/site-packages/pymysql/connections.py", line 353, in __init__
    self.connect()
  File "/usr/local/lib/python3.8/site-packages/pymysql/connections.py", line 664, in connect
    raise exc
pymysql.err.OperationalError: (2003, "Can't connect to MySQL server on 'backendqa0001.globo.correio.biz' (timed out)")

2021-08-10 00:33:35,536 - ERROR - An Error occurred while handling migrations: Traceback (most recent call last):
  File "/usr/local/lib/python3.8/site-packages/pymysql/connections.py", line 613, in connect
    sock = socket.create_connection(
  File "/usr/local/lib/python3.8/socket.py", line 808, in create_connection
    raise err
  File "/usr/local/lib/python3.8/socket.py", line 796, in create_connection
    sock.connect(sa)
socket.timeout: timed out

During handling of the above exception, another exception occurred:

Traceback (most recent call last):
  File "main.py", line 25, in handler_service
    handler_migration = IntegratorService(logger)
  File "/opt/globo/integrator/service.py", line 20, in __init__
    self.globomail_repository = GlobomailRepository()
  File "/opt/globo/repositories/globomail.py", line 12, in __init__
    self.connection = pymysql.connect(host=self.hostname, user=self.username, password=self.password,
  File "/usr/local/lib/python3.8/site-packages/pymysql/connections.py", line 353, in __init__
    self.connect()
  File "/usr/local/lib/python3.8/site-packages/pymysql/connections.py", line 664, in connect
    raise exc
pymysql.err.OperationalError: (2003, "Can't connect to MySQL server on 'backendqa0001.globo.correio.biz' (timed out)")

2021-08-10 00:34:45,841 - ERROR - An Error occurred while handling migrations: Traceback (most recent call last):
  File "/usr/local/lib/python3.8/site-packages/pymysql/connections.py", line 613, in connect
    sock = socket.create_connection(
  File "/usr/local/lib/python3.8/socket.py", line 808, in create_connection
    raise err
  File "/usr/local/lib/python3.8/socket.py", line 796, in create_connection
    sock.connect(sa)
socket.timeout: timed out

During handling of the above exception, another exception occurred:

Traceback (most recent call last):
  File "main.py", line 25, in handler_service
    handler_migration = IntegratorService(logger)
  File "/opt/globo/integrator/service.py", line 20, in __init__
    self.globomail_repository = GlobomailRepository()
  File "/opt/globo/repositories/globomail.py", line 12, in __init__
    self.connection = pymysql.connect(host=self.hostname, user=self.username, password=self.password,
  File "/usr/local/lib/python3.8/site-packages/pymysql/connections.py", line 353, in __init__
    self.connect()
  File "/usr/local/lib/python3.8/site-packages/pymysql/connections.py", line 664, in connect
    raise exc
pymysql.err.OperationalError: (2003, "Can't connect to MySQL server on 'backendqa0001.globo.correio.biz' (timed out)")

2021-08-10 00:35:56,128 - ERROR - An Error occurred while handling migrations: Traceback (most recent call last):
  File "/usr/local/lib/python3.8/site-packages/pymysql/connections.py", line 613, in connect
    sock = socket.create_connection(
  File "/usr/local/lib/python3.8/socket.py", line 808, in create_connection
    raise err
  File "/usr/local/lib/python3.8/socket.py", line 796, in create_connection
    sock.connect(sa)
socket.timeout: timed out

During handling of the above exception, another exception occurred:

Traceback (most recent call last):
  File "main.py", line 25, in handler_service
    handler_migration = IntegratorService(logger)
  File "/opt/globo/integrator/service.py", line 20, in __init__
    self.globomail_repository = GlobomailRepository()
  File "/opt/globo/repositories/globomail.py", line 12, in __init__
    self.connection = pymysql.connect(host=self.hostname, user=self.username, password=self.password,
  File "/usr/local/lib/python3.8/site-packages/pymysql/connections.py", line 353, in __init__
    self.connect()
  File "/usr/local/lib/python3.8/site-packages/pymysql/connections.py", line 664, in connect
    raise exc
pymysql.err.OperationalError: (2003, "Can't connect to MySQL server on 'backendqa0001.globo.correio.biz' (timed out)")

2021-08-10 00:37:06,446 - ERROR - An Error occurred while handling migrations: Traceback (most recent call last):
  File "/usr/local/lib/python3.8/site-packages/pymysql/connections.py", line 613, in connect
    sock = socket.create_connection(
  File "/usr/local/lib/python3.8/socket.py", line 808, in create_connection
    raise err
  File "/usr/local/lib/python3.8/socket.py", line 796, in create_connection
    sock.connect(sa)
socket.timeout: timed out

During handling of the above exception, another exception occurred:

Traceback (most recent call last):
  File "main.py", line 25, in handler_service
    handler_migration = IntegratorService(logger)
  File "/opt/globo/integrator/service.py", line 20, in __init__
    self.globomail_repository = GlobomailRepository()
  File "/opt/globo/repositories/globomail.py", line 12, in __init__
    self.connection = pymysql.connect(host=self.hostname, user=self.username, password=self.password,
  File "/usr/local/lib/python3.8/site-packages/pymysql/connections.py", line 353, in __init__
    self.connect()
  File "/usr/local/lib/python3.8/site-packages/pymysql/connections.py", line 664, in connect
    raise exc
pymysql.err.OperationalError: (2003, "Can't connect to MySQL server on 'backendqa0001.globo.correio.biz' (timed out)")

2021-08-10 00:38:16,760 - ERROR - An Error occurred while handling migrations: Traceback (most recent call last):
  File "/usr/local/lib/python3.8/site-packages/pymysql/connections.py", line 613, in connect
    sock = socket.create_connection(
  File "/usr/local/lib/python3.8/socket.py", line 808, in create_connection
    raise err
  File "/usr/local/lib/python3.8/socket.py", line 796, in create_connection
    sock.connect(sa)
socket.timeout: timed out

During handling of the above exception, another exception occurred:

Traceback (most recent call last):
  File "main.py", line 25, in handler_service
    handler_migration = IntegratorService(logger)
  File "/opt/globo/integrator/service.py", line 20, in __init__
    self.globomail_repository = GlobomailRepository()
  File "/opt/globo/repositories/globomail.py", line 12, in __init__
    self.connection = pymysql.connect(host=self.hostname, user=self.username, password=self.password,
  File "/usr/local/lib/python3.8/site-packages/pymysql/connections.py", line 353, in __init__
    self.connect()
  File "/usr/local/lib/python3.8/site-packages/pymysql/connections.py", line 664, in connect
    raise exc
pymysql.err.OperationalError: (2003, "Can't connect to MySQL server on 'backendqa0001.globo.correio.biz' (timed out)")

2021-08-10 00:39:27,140 - ERROR - An Error occurred while handling migrations: Traceback (most recent call last):
  File "/usr/local/lib/python3.8/site-packages/pymysql/connections.py", line 613, in connect
    sock = socket.create_connection(
  File "/usr/local/lib/python3.8/socket.py", line 808, in create_connection
    raise err
  File "/usr/local/lib/python3.8/socket.py", line 796, in create_connection
    sock.connect(sa)
socket.timeout: timed out

During handling of the above exception, another exception occurred:

Traceback (most recent call last):
  File "main.py", line 25, in handler_service
    handler_migration = IntegratorService(logger)
  File "/opt/globo/integrator/service.py", line 20, in __init__
    self.globomail_repository = GlobomailRepository()
  File "/opt/globo/repositories/globomail.py", line 12, in __init__
    self.connection = pymysql.connect(host=self.hostname, user=self.username, password=self.password,
  File "/usr/local/lib/python3.8/site-packages/pymysql/connections.py", line 353, in __init__
    self.connect()
  File "/usr/local/lib/python3.8/site-packages/pymysql/connections.py", line 664, in connect
    raise exc
pymysql.err.OperationalError: (2003, "Can't connect to MySQL server on 'backendqa0001.globo.correio.biz' (timed out)")

2021-08-10 00:40:37,492 - ERROR - An Error occurred while handling migrations: Traceback (most recent call last):
  File "/usr/local/lib/python3.8/site-packages/pymysql/connections.py", line 613, in connect
    sock = socket.create_connection(
  File "/usr/local/lib/python3.8/socket.py", line 808, in create_connection
    raise err
  File "/usr/local/lib/python3.8/socket.py", line 796, in create_connection
    sock.connect(sa)
socket.timeout: timed out

During handling of the above exception, another exception occurred:

Traceback (most recent call last):
  File "main.py", line 25, in handler_service
    handler_migration = IntegratorService(logger)
  File "/opt/globo/integrator/service.py", line 20, in __init__
    self.globomail_repository = GlobomailRepository()
  File "/opt/globo/repositories/globomail.py", line 12, in __init__
    self.connection = pymysql.connect(host=self.hostname, user=self.username, password=self.password,
  File "/usr/local/lib/python3.8/site-packages/pymysql/connections.py", line 353, in __init__
    self.connect()
  File "/usr/local/lib/python3.8/site-packages/pymysql/connections.py", line 664, in connect
    raise exc
pymysql.err.OperationalError: (2003, "Can't connect to MySQL server on 'backendqa0001.globo.correio.biz' (timed out)")

2021-08-10 00:41:48,211 - ERROR - An Error occurred while handling migrations: Traceback (most recent call last):
  File "/usr/local/lib/python3.8/site-packages/pymysql/connections.py", line 613, in connect
    sock = socket.create_connection(
  File "/usr/local/lib/python3.8/socket.py", line 808, in create_connection
    raise err
  File "/usr/local/lib/python3.8/socket.py", line 796, in create_connection
    sock.connect(sa)
socket.timeout: timed out

During handling of the above exception, another exception occurred:

Traceback (most recent call last):
  File "main.py", line 25, in handler_service
    handler_migration = IntegratorService(logger)
  File "/opt/globo/integrator/service.py", line 20, in __init__
    self.globomail_repository = GlobomailRepository()
  File "/opt/globo/repositories/globomail.py", line 12, in __init__
    self.connection = pymysql.connect(host=self.hostname, user=self.username, password=self.password,
  File "/usr/local/lib/python3.8/site-packages/pymysql/connections.py", line 353, in __init__
    self.connect()
  File "/usr/local/lib/python3.8/site-packages/pymysql/connections.py", line 664, in connect
    raise exc
pymysql.err.OperationalError: (2003, "Can't connect to MySQL server on 'backendqa0001.globo.correio.biz' (timed out)")

2021-08-10 00:42:58,550 - ERROR - An Error occurred while handling migrations: Traceback (most recent call last):
  File "/usr/local/lib/python3.8/site-packages/pymysql/connections.py", line 613, in connect
    sock = socket.create_connection(
  File "/usr/local/lib/python3.8/socket.py", line 808, in create_connection
    raise err
  File "/usr/local/lib/python3.8/socket.py", line 796, in create_connection
    sock.connect(sa)
socket.timeout: timed out

During handling of the above exception, another exception occurred:

Traceback (most recent call last):
  File "main.py", line 25, in handler_service
    handler_migration = IntegratorService(logger)
  File "/opt/globo/integrator/service.py", line 20, in __init__
    self.globomail_repository = GlobomailRepository()
  File "/opt/globo/repositories/globomail.py", line 12, in __init__
    self.connection = pymysql.connect(host=self.hostname, user=self.username, password=self.password,
  File "/usr/local/lib/python3.8/site-packages/pymysql/connections.py", line 353, in __init__
    self.connect()
  File "/usr/local/lib/python3.8/site-packages/pymysql/connections.py", line 664, in connect
    raise exc
pymysql.err.OperationalError: (2003, "Can't connect to MySQL server on 'backendqa0001.globo.correio.biz' (timed out)")

2021-08-10 00:44:08,869 - ERROR - An Error occurred while handling migrations: Traceback (most recent call last):
  File "/usr/local/lib/python3.8/site-packages/pymysql/connections.py", line 613, in connect
    sock = socket.create_connection(
  File "/usr/local/lib/python3.8/socket.py", line 808, in create_connection
    raise err
  File "/usr/local/lib/python3.8/socket.py", line 796, in create_connection
    sock.connect(sa)
socket.timeout: timed out

During handling of the above exception, another exception occurred:

Traceback (most recent call last):
  File "main.py", line 25, in handler_service
    handler_migration = IntegratorService(logger)
  File "/opt/globo/integrator/service.py", line 20, in __init__
    self.globomail_repository = GlobomailRepository()
  File "/opt/globo/repositories/globomail.py", line 12, in __init__
    self.connection = pymysql.connect(host=self.hostname, user=self.username, password=self.password,
  File "/usr/local/lib/python3.8/site-packages/pymysql/connections.py", line 353, in __init__
    self.connect()
  File "/usr/local/lib/python3.8/site-packages/pymysql/connections.py", line 664, in connect
    raise exc
pymysql.err.OperationalError: (2003, "Can't connect to MySQL server on 'backendqa0001.globo.correio.biz' (timed out)")

2021-08-10 00:45:19,243 - ERROR - An Error occurred while handling migrations: Traceback (most recent call last):
  File "/usr/local/lib/python3.8/site-packages/pymysql/connections.py", line 613, in connect
    sock = socket.create_connection(
  File "/usr/local/lib/python3.8/socket.py", line 808, in create_connection
    raise err
  File "/usr/local/lib/python3.8/socket.py", line 796, in create_connection
    sock.connect(sa)
socket.timeout: timed out

During handling of the above exception, another exception occurred:

Traceback (most recent call last):
  File "main.py", line 25, in handler_service
    handler_migration = IntegratorService(logger)
  File "/opt/globo/integrator/service.py", line 20, in __init__
    self.globomail_repository = GlobomailRepository()
  File "/opt/globo/repositories/globomail.py", line 12, in __init__
    self.connection = pymysql.connect(host=self.hostname, user=self.username, password=self.password,
  File "/usr/local/lib/python3.8/site-packages/pymysql/connections.py", line 353, in __init__
    self.connect()
  File "/usr/local/lib/python3.8/site-packages/pymysql/connections.py", line 664, in connect
    raise exc
pymysql.err.OperationalError: (2003, "Can't connect to MySQL server on 'backendqa0001.globo.correio.biz' (timed out)")

2021-08-10 00:46:29,544 - ERROR - An Error occurred while handling migrations: Traceback (most recent call last):
  File "/usr/local/lib/python3.8/site-packages/pymysql/connections.py", line 613, in connect
    sock = socket.create_connection(
  File "/usr/local/lib/python3.8/socket.py", line 808, in create_connection
    raise err
  File "/usr/local/lib/python3.8/socket.py", line 796, in create_connection
    sock.connect(sa)
socket.timeout: timed out

During handling of the above exception, another exception occurred:

Traceback (most recent call last):
  File "main.py", line 25, in handler_service
    handler_migration = IntegratorService(logger)
  File "/opt/globo/integrator/service.py", line 20, in __init__
    self.globomail_repository = GlobomailRepository()
  File "/opt/globo/repositories/globomail.py", line 12, in __init__
    self.connection = pymysql.connect(host=self.hostname, user=self.username, password=self.password,
  File "/usr/local/lib/python3.8/site-packages/pymysql/connections.py", line 353, in __init__
    self.connect()
  File "/usr/local/lib/python3.8/site-packages/pymysql/connections.py", line 664, in connect
    raise exc
pymysql.err.OperationalError: (2003, "Can't connect to MySQL server on 'backendqa0001.globo.correio.biz' (timed out)")

2021-08-10 00:47:39,883 - ERROR - An Error occurred while handling migrations: Traceback (most recent call last):
  File "/usr/local/lib/python3.8/site-packages/pymysql/connections.py", line 613, in connect
    sock = socket.create_connection(
  File "/usr/local/lib/python3.8/socket.py", line 808, in create_connection
    raise err
  File "/usr/local/lib/python3.8/socket.py", line 796, in create_connection
    sock.connect(sa)
socket.timeout: timed out

During handling of the above exception, another exception occurred:

Traceback (most recent call last):
  File "main.py", line 25, in handler_service
    handler_migration = IntegratorService(logger)
  File "/opt/globo/integrator/service.py", line 20, in __init__
    self.globomail_repository = GlobomailRepository()
  File "/opt/globo/repositories/globomail.py", line 12, in __init__
    self.connection = pymysql.connect(host=self.hostname, user=self.username, password=self.password,
  File "/usr/local/lib/python3.8/site-packages/pymysql/connections.py", line 353, in __init__
    self.connect()
  File "/usr/local/lib/python3.8/site-packages/pymysql/connections.py", line 664, in connect
    raise exc
pymysql.err.OperationalError: (2003, "Can't connect to MySQL server on 'backendqa0001.globo.correio.biz' (timed out)")

2021-08-10 00:48:50,229 - ERROR - An Error occurred while handling migrations: Traceback (most recent call last):
  File "/usr/local/lib/python3.8/site-packages/pymysql/connections.py", line 613, in connect
    sock = socket.create_connection(
  File "/usr/local/lib/python3.8/socket.py", line 808, in create_connection
    raise err
  File "/usr/local/lib/python3.8/socket.py", line 796, in create_connection
    sock.connect(sa)
socket.timeout: timed out

During handling of the above exception, another exception occurred:

Traceback (most recent call last):
  File "main.py", line 25, in handler_service
    handler_migration = IntegratorService(logger)
  File "/opt/globo/integrator/service.py", line 20, in __init__
    self.globomail_repository = GlobomailRepository()
  File "/opt/globo/repositories/globomail.py", line 12, in __init__
    self.connection = pymysql.connect(host=self.hostname, user=self.username, password=self.password,
  File "/usr/local/lib/python3.8/site-packages/pymysql/connections.py", line 353, in __init__
    self.connect()
  File "/usr/local/lib/python3.8/site-packages/pymysql/connections.py", line 664, in connect
    raise exc
pymysql.err.OperationalError: (2003, "Can't connect to MySQL server on 'backendqa0001.globo.correio.biz' (timed out)")

2021-08-10 00:50:00,501 - ERROR - An Error occurred while handling migrations: Traceback (most recent call last):
  File "/usr/local/lib/python3.8/site-packages/pymysql/connections.py", line 613, in connect
    sock = socket.create_connection(
  File "/usr/local/lib/python3.8/socket.py", line 808, in create_connection
    raise err
  File "/usr/local/lib/python3.8/socket.py", line 796, in create_connection
    sock.connect(sa)
socket.timeout: timed out

During handling of the above exception, another exception occurred:

Traceback (most recent call last):
  File "main.py", line 25, in handler_service
    handler_migration = IntegratorService(logger)
  File "/opt/globo/integrator/service.py", line 20, in __init__
    self.globomail_repository = GlobomailRepository()
  File "/opt/globo/repositories/globomail.py", line 12, in __init__
    self.connection = pymysql.connect(host=self.hostname, user=self.username, password=self.password,
  File "/usr/local/lib/python3.8/site-packages/pymysql/connections.py", line 353, in __init__
    self.connect()
  File "/usr/local/lib/python3.8/site-packages/pymysql/connections.py", line 664, in connect
    raise exc
pymysql.err.OperationalError: (2003, "Can't connect to MySQL server on 'backendqa0001.globo.correio.biz' (timed out)")

2021-08-10 00:51:10,790 - ERROR - An Error occurred while handling migrations: Traceback (most recent call last):
  File "/usr/local/lib/python3.8/site-packages/pymysql/connections.py", line 613, in connect
    sock = socket.create_connection(
  File "/usr/local/lib/python3.8/socket.py", line 808, in create_connection
    raise err
  File "/usr/local/lib/python3.8/socket.py", line 796, in create_connection
    sock.connect(sa)
socket.timeout: timed out

During handling of the above exception, another exception occurred:

Traceback (most recent call last):
  File "main.py", line 25, in handler_service
    handler_migration = IntegratorService(logger)
  File "/opt/globo/integrator/service.py", line 20, in __init__
    self.globomail_repository = GlobomailRepository()
  File "/opt/globo/repositories/globomail.py", line 12, in __init__
    self.connection = pymysql.connect(host=self.hostname, user=self.username, password=self.password,
  File "/usr/local/lib/python3.8/site-packages/pymysql/connections.py", line 353, in __init__
    self.connect()
  File "/usr/local/lib/python3.8/site-packages/pymysql/connections.py", line 664, in connect
    raise exc
pymysql.err.OperationalError: (2003, "Can't connect to MySQL server on 'backendqa0001.globo.correio.biz' (timed out)")

2021-08-10 00:52:21,081 - ERROR - An Error occurred while handling migrations: Traceback (most recent call last):
  File "/usr/local/lib/python3.8/site-packages/pymysql/connections.py", line 613, in connect
    sock = socket.create_connection(
  File "/usr/local/lib/python3.8/socket.py", line 808, in create_connection
    raise err
  File "/usr/local/lib/python3.8/socket.py", line 796, in create_connection
    sock.connect(sa)
socket.timeout: timed out

During handling of the above exception, another exception occurred:

Traceback (most recent call last):
  File "main.py", line 25, in handler_service
    handler_migration = IntegratorService(logger)
  File "/opt/globo/integrator/service.py", line 20, in __init__
    self.globomail_repository = GlobomailRepository()
  File "/opt/globo/repositories/globomail.py", line 12, in __init__
    self.connection = pymysql.connect(host=self.hostname, user=self.username, password=self.password,
  File "/usr/local/lib/python3.8/site-packages/pymysql/connections.py", line 353, in __init__
    self.connect()
  File "/usr/local/lib/python3.8/site-packages/pymysql/connections.py", line 664, in connect
    raise exc
pymysql.err.OperationalError: (2003, "Can't connect to MySQL server on 'backendqa0001.globo.correio.biz' (timed out)")

2021-08-10 00:53:31,427 - ERROR - An Error occurred while handling migrations: Traceback (most recent call last):
  File "/usr/local/lib/python3.8/site-packages/pymysql/connections.py", line 613, in connect
    sock = socket.create_connection(
  File "/usr/local/lib/python3.8/socket.py", line 808, in create_connection
    raise err
  File "/usr/local/lib/python3.8/socket.py", line 796, in create_connection
    sock.connect(sa)
socket.timeout: timed out

During handling of the above exception, another exception occurred:

Traceback (most recent call last):
  File "main.py", line 25, in handler_service
    handler_migration = IntegratorService(logger)
  File "/opt/globo/integrator/service.py", line 20, in __init__
    self.globomail_repository = GlobomailRepository()
  File "/opt/globo/repositories/globomail.py", line 12, in __init__
    self.connection = pymysql.connect(host=self.hostname, user=self.username, password=self.password,
  File "/usr/local/lib/python3.8/site-packages/pymysql/connections.py", line 353, in __init__
    self.connect()
  File "/usr/local/lib/python3.8/site-packages/pymysql/connections.py", line 664, in connect
    raise exc
pymysql.err.OperationalError: (2003, "Can't connect to MySQL server on 'backendqa0001.globo.correio.biz' (timed out)")

2021-08-10 00:54:41,752 - ERROR - An Error occurred while handling migrations: Traceback (most recent call last):
  File "/usr/local/lib/python3.8/site-packages/pymysql/connections.py", line 613, in connect
    sock = socket.create_connection(
  File "/usr/local/lib/python3.8/socket.py", line 808, in create_connection
    raise err
  File "/usr/local/lib/python3.8/socket.py", line 796, in create_connection
    sock.connect(sa)
socket.timeout: timed out

During handling of the above exception, another exception occurred:

Traceback (most recent call last):
  File "main.py", line 25, in handler_service
    handler_migration = IntegratorService(logger)
  File "/opt/globo/integrator/service.py", line 20, in __init__
    self.globomail_repository = GlobomailRepository()
  File "/opt/globo/repositories/globomail.py", line 12, in __init__
    self.connection = pymysql.connect(host=self.hostname, user=self.username, password=self.password,
  File "/usr/local/lib/python3.8/site-packages/pymysql/connections.py", line 353, in __init__
    self.connect()
  File "/usr/local/lib/python3.8/site-packages/pymysql/connections.py", line 664, in connect
    raise exc
pymysql.err.OperationalError: (2003, "Can't connect to MySQL server on 'backendqa0001.globo.correio.biz' (timed out)")

2021-08-10 00:55:52,057 - ERROR - An Error occurred while handling migrations: Traceback (most recent call last):
  File "/usr/local/lib/python3.8/site-packages/pymysql/connections.py", line 613, in connect
    sock = socket.create_connection(
  File "/usr/local/lib/python3.8/socket.py", line 808, in create_connection
    raise err
  File "/usr/local/lib/python3.8/socket.py", line 796, in create_connection
    sock.connect(sa)
socket.timeout: timed out

During handling of the above exception, another exception occurred:

Traceback (most recent call last):
  File "main.py", line 25, in handler_service
    handler_migration = IntegratorService(logger)
  File "/opt/globo/integrator/service.py", line 20, in __init__
    self.globomail_repository = GlobomailRepository()
  File "/opt/globo/repositories/globomail.py", line 12, in __init__
    self.connection = pymysql.connect(host=self.hostname, user=self.username, password=self.password,
  File "/usr/local/lib/python3.8/site-packages/pymysql/connections.py", line 353, in __init__
    self.connect()
  File "/usr/local/lib/python3.8/site-packages/pymysql/connections.py", line 664, in connect
    raise exc
pymysql.err.OperationalError: (2003, "Can't connect to MySQL server on 'backendqa0001.globo.correio.biz' (timed out)")

2021-08-10 00:57:02,390 - ERROR - An Error occurred while handling migrations: Traceback (most recent call last):
  File "/usr/local/lib/python3.8/site-packages/pymysql/connections.py", line 613, in connect
    sock = socket.create_connection(
  File "/usr/local/lib/python3.8/socket.py", line 808, in create_connection
    raise err
  File "/usr/local/lib/python3.8/socket.py", line 796, in create_connection
    sock.connect(sa)
socket.timeout: timed out

During handling of the above exception, another exception occurred:

Traceback (most recent call last):
  File "main.py", line 25, in handler_service
    handler_migration = IntegratorService(logger)
  File "/opt/globo/integrator/service.py", line 20, in __init__
    self.globomail_repository = GlobomailRepository()
  File "/opt/globo/repositories/globomail.py", line 12, in __init__
    self.connection = pymysql.connect(host=self.hostname, user=self.username, password=self.password,
  File "/usr/local/lib/python3.8/site-packages/pymysql/connections.py", line 353, in __init__
    self.connect()
  File "/usr/local/lib/python3.8/site-packages/pymysql/connections.py", line 664, in connect
    raise exc
pymysql.err.OperationalError: (2003, "Can't connect to MySQL server on 'backendqa0001.globo.correio.biz' (timed out)")

2021-08-10 00:58:12,699 - ERROR - An Error occurred while handling migrations: Traceback (most recent call last):
  File "/usr/local/lib/python3.8/site-packages/pymysql/connections.py", line 613, in connect
    sock = socket.create_connection(
  File "/usr/local/lib/python3.8/socket.py", line 808, in create_connection
    raise err
  File "/usr/local/lib/python3.8/socket.py", line 796, in create_connection
    sock.connect(sa)
socket.timeout: timed out

During handling of the above exception, another exception occurred:

Traceback (most recent call last):
  File "main.py", line 25, in handler_service
    handler_migration = IntegratorService(logger)
  File "/opt/globo/integrator/service.py", line 20, in __init__
    self.globomail_repository = GlobomailRepository()
  File "/opt/globo/repositories/globomail.py", line 12, in __init__
    self.connection = pymysql.connect(host=self.hostname, user=self.username, password=self.password,
  File "/usr/local/lib/python3.8/site-packages/pymysql/connections.py", line 353, in __init__
    self.connect()
  File "/usr/local/lib/python3.8/site-packages/pymysql/connections.py", line 664, in connect
    raise exc
pymysql.err.OperationalError: (2003, "Can't connect to MySQL server on 'backendqa0001.globo.correio.biz' (timed out)")

2021-08-10 00:59:23,027 - ERROR - An Error occurred while handling migrations: Traceback (most recent call last):
  File "/usr/local/lib/python3.8/site-packages/pymysql/connections.py", line 613, in connect
    sock = socket.create_connection(
  File "/usr/local/lib/python3.8/socket.py", line 808, in create_connection
    raise err
  File "/usr/local/lib/python3.8/socket.py", line 796, in create_connection
    sock.connect(sa)
socket.timeout: timed out

During handling of the above exception, another exception occurred:

Traceback (most recent call last):
  File "main.py", line 25, in handler_service
    handler_migration = IntegratorService(logger)
  File "/opt/globo/integrator/service.py", line 20, in __init__
    self.globomail_repository = GlobomailRepository()
  File "/opt/globo/repositories/globomail.py", line 12, in __init__
    self.connection = pymysql.connect(host=self.hostname, user=self.username, password=self.password,
  File "/usr/local/lib/python3.8/site-packages/pymysql/connections.py", line 353, in __init__
    self.connect()
  File "/usr/local/lib/python3.8/site-packages/pymysql/connections.py", line 664, in connect
    raise exc
pymysql.err.OperationalError: (2003, "Can't connect to MySQL server on 'backendqa0001.globo.correio.biz' (timed out)")

2021-08-10 01:00:33,325 - ERROR - An Error occurred while handling migrations: Traceback (most recent call last):
  File "/usr/local/lib/python3.8/site-packages/pymysql/connections.py", line 613, in connect
    sock = socket.create_connection(
  File "/usr/local/lib/python3.8/socket.py", line 808, in create_connection
    raise err
  File "/usr/local/lib/python3.8/socket.py", line 796, in create_connection
    sock.connect(sa)
socket.timeout: timed out

During handling of the above exception, another exception occurred:

Traceback (most recent call last):
  File "main.py", line 25, in handler_service
    handler_migration = IntegratorService(logger)
  File "/opt/globo/integrator/service.py", line 20, in __init__
    self.globomail_repository = GlobomailRepository()
  File "/opt/globo/repositories/globomail.py", line 12, in __init__
    self.connection = pymysql.connect(host=self.hostname, user=self.username, password=self.password,
  File "/usr/local/lib/python3.8/site-packages/pymysql/connections.py", line 353, in __init__
    self.connect()
  File "/usr/local/lib/python3.8/site-packages/pymysql/connections.py", line 664, in connect
    raise exc
pymysql.err.OperationalError: (2003, "Can't connect to MySQL server on 'backendqa0001.globo.correio.biz' (timed out)")

2021-08-10 01:01:43,663 - ERROR - An Error occurred while handling migrations: Traceback (most recent call last):
  File "/usr/local/lib/python3.8/site-packages/pymysql/connections.py", line 613, in connect
    sock = socket.create_connection(
  File "/usr/local/lib/python3.8/socket.py", line 808, in create_connection
    raise err
  File "/usr/local/lib/python3.8/socket.py", line 796, in create_connection
    sock.connect(sa)
socket.timeout: timed out

During handling of the above exception, another exception occurred:

Traceback (most recent call last):
  File "main.py", line 25, in handler_service
    handler_migration = IntegratorService(logger)
  File "/opt/globo/integrator/service.py", line 20, in __init__
    self.globomail_repository = GlobomailRepository()
  File "/opt/globo/repositories/globomail.py", line 12, in __init__
    self.connection = pymysql.connect(host=self.hostname, user=self.username, password=self.password,
  File "/usr/local/lib/python3.8/site-packages/pymysql/connections.py", line 353, in __init__
    self.connect()
  File "/usr/local/lib/python3.8/site-packages/pymysql/connections.py", line 664, in connect
    raise exc
pymysql.err.OperationalError: (2003, "Can't connect to MySQL server on 'backendqa0001.globo.correio.biz' (timed out)")

2021-08-10 01:02:53,977 - ERROR - An Error occurred while handling migrations: Traceback (most recent call last):
  File "/usr/local/lib/python3.8/site-packages/pymysql/connections.py", line 613, in connect
    sock = socket.create_connection(
  File "/usr/local/lib/python3.8/socket.py", line 808, in create_connection
    raise err
  File "/usr/local/lib/python3.8/socket.py", line 796, in create_connection
    sock.connect(sa)
socket.timeout: timed out

During handling of the above exception, another exception occurred:

Traceback (most recent call last):
  File "main.py", line 25, in handler_service
    handler_migration = IntegratorService(logger)
  File "/opt/globo/integrator/service.py", line 20, in __init__
    self.globomail_repository = GlobomailRepository()
  File "/opt/globo/repositories/globomail.py", line 12, in __init__
    self.connection = pymysql.connect(host=self.hostname, user=self.username, password=self.password,
  File "/usr/local/lib/python3.8/site-packages/pymysql/connections.py", line 353, in __init__
    self.connect()
  File "/usr/local/lib/python3.8/site-packages/pymysql/connections.py", line 664, in connect
    raise exc
pymysql.err.OperationalError: (2003, "Can't connect to MySQL server on 'backendqa0001.globo.correio.biz' (timed out)")

2021-08-10 01:04:04,281 - ERROR - An Error occurred while handling migrations: Traceback (most recent call last):
  File "/usr/local/lib/python3.8/site-packages/pymysql/connections.py", line 613, in connect
    sock = socket.create_connection(
  File "/usr/local/lib/python3.8/socket.py", line 808, in create_connection
    raise err
  File "/usr/local/lib/python3.8/socket.py", line 796, in create_connection
    sock.connect(sa)
socket.timeout: timed out

During handling of the above exception, another exception occurred:

Traceback (most recent call last):
  File "main.py", line 25, in handler_service
    handler_migration = IntegratorService(logger)
  File "/opt/globo/integrator/service.py", line 20, in __init__
    self.globomail_repository = GlobomailRepository()
  File "/opt/globo/repositories/globomail.py", line 12, in __init__
    self.connection = pymysql.connect(host=self.hostname, user=self.username, password=self.password,
  File "/usr/local/lib/python3.8/site-packages/pymysql/connections.py", line 353, in __init__
    self.connect()
  File "/usr/local/lib/python3.8/site-packages/pymysql/connections.py", line 664, in connect
    raise exc
pymysql.err.OperationalError: (2003, "Can't connect to MySQL server on 'backendqa0001.globo.correio.biz' (timed out)")

2021-08-10 01:05:14,608 - ERROR - An Error occurred while handling migrations: Traceback (most recent call last):
  File "/usr/local/lib/python3.8/site-packages/pymysql/connections.py", line 613, in connect
    sock = socket.create_connection(
  File "/usr/local/lib/python3.8/socket.py", line 808, in create_connection
    raise err
  File "/usr/local/lib/python3.8/socket.py", line 796, in create_connection
    sock.connect(sa)
socket.timeout: timed out

During handling of the above exception, another exception occurred:

Traceback (most recent call last):
  File "main.py", line 25, in handler_service
    handler_migration = IntegratorService(logger)
  File "/opt/globo/integrator/service.py", line 20, in __init__
    self.globomail_repository = GlobomailRepository()
  File "/opt/globo/repositories/globomail.py", line 12, in __init__
    self.connection = pymysql.connect(host=self.hostname, user=self.username, password=self.password,
  File "/usr/local/lib/python3.8/site-packages/pymysql/connections.py", line 353, in __init__
    self.connect()
  File "/usr/local/lib/python3.8/site-packages/pymysql/connections.py", line 664, in connect
    raise exc
pymysql.err.OperationalError: (2003, "Can't connect to MySQL server on 'backendqa0001.globo.correio.biz' (timed out)")

2021-08-10 01:06:24,919 - ERROR - An Error occurred while handling migrations: Traceback (most recent call last):
  File "/usr/local/lib/python3.8/site-packages/pymysql/connections.py", line 613, in connect
    sock = socket.create_connection(
  File "/usr/local/lib/python3.8/socket.py", line 808, in create_connection
    raise err
  File "/usr/local/lib/python3.8/socket.py", line 796, in create_connection
    sock.connect(sa)
socket.timeout: timed out

During handling of the above exception, another exception occurred:

Traceback (most recent call last):
  File "main.py", line 25, in handler_service
    handler_migration = IntegratorService(logger)
  File "/opt/globo/integrator/service.py", line 20, in __init__
    self.globomail_repository = GlobomailRepository()
  File "/opt/globo/repositories/globomail.py", line 12, in __init__
    self.connection = pymysql.connect(host=self.hostname, user=self.username, password=self.password,
  File "/usr/local/lib/python3.8/site-packages/pymysql/connections.py", line 353, in __init__
    self.connect()
  File "/usr/local/lib/python3.8/site-packages/pymysql/connections.py", line 664, in connect
    raise exc
pymysql.err.OperationalError: (2003, "Can't connect to MySQL server on 'backendqa0001.globo.correio.biz' (timed out)")

2021-08-10 01:07:35,263 - ERROR - An Error occurred while handling migrations: Traceback (most recent call last):
  File "/usr/local/lib/python3.8/site-packages/pymysql/connections.py", line 613, in connect
    sock = socket.create_connection(
  File "/usr/local/lib/python3.8/socket.py", line 808, in create_connection
    raise err
  File "/usr/local/lib/python3.8/socket.py", line 796, in create_connection
    sock.connect(sa)
socket.timeout: timed out

During handling of the above exception, another exception occurred:

Traceback (most recent call last):
  File "main.py", line 25, in handler_service
    handler_migration = IntegratorService(logger)
  File "/opt/globo/integrator/service.py", line 20, in __init__
    self.globomail_repository = GlobomailRepository()
  File "/opt/globo/repositories/globomail.py", line 12, in __init__
    self.connection = pymysql.connect(host=self.hostname, user=self.username, password=self.password,
  File "/usr/local/lib/python3.8/site-packages/pymysql/connections.py", line 353, in __init__
    self.connect()
  File "/usr/local/lib/python3.8/site-packages/pymysql/connections.py", line 664, in connect
    raise exc
pymysql.err.OperationalError: (2003, "Can't connect to MySQL server on 'backendqa0001.globo.correio.biz' (timed out)")

2021-08-10 01:08:46,002 - ERROR - An Error occurred while handling migrations: Traceback (most recent call last):
  File "/usr/local/lib/python3.8/site-packages/pymysql/connections.py", line 613, in connect
    sock = socket.create_connection(
  File "/usr/local/lib/python3.8/socket.py", line 808, in create_connection
    raise err
  File "/usr/local/lib/python3.8/socket.py", line 796, in create_connection
    sock.connect(sa)
socket.timeout: timed out

During handling of the above exception, another exception occurred:

Traceback (most recent call last):
  File "main.py", line 25, in handler_service
    handler_migration = IntegratorService(logger)
  File "/opt/globo/integrator/service.py", line 20, in __init__
    self.globomail_repository = GlobomailRepository()
  File "/opt/globo/repositories/globomail.py", line 12, in __init__
    self.connection = pymysql.connect(host=self.hostname, user=self.username, password=self.password,
  File "/usr/local/lib/python3.8/site-packages/pymysql/connections.py", line 353, in __init__
    self.connect()
  File "/usr/local/lib/python3.8/site-packages/pymysql/connections.py", line 664, in connect
    raise exc
pymysql.err.OperationalError: (2003, "Can't connect to MySQL server on 'backendqa0001.globo.correio.biz' (timed out)")

2021-08-10 01:09:56,315 - ERROR - An Error occurred while handling migrations: Traceback (most recent call last):
  File "/usr/local/lib/python3.8/site-packages/pymysql/connections.py", line 613, in connect
    sock = socket.create_connection(
  File "/usr/local/lib/python3.8/socket.py", line 808, in create_connection
    raise err
  File "/usr/local/lib/python3.8/socket.py", line 796, in create_connection
    sock.connect(sa)
socket.timeout: timed out

During handling of the above exception, another exception occurred:

Traceback (most recent call last):
  File "main.py", line 25, in handler_service
    handler_migration = IntegratorService(logger)
  File "/opt/globo/integrator/service.py", line 20, in __init__
    self.globomail_repository = GlobomailRepository()
  File "/opt/globo/repositories/globomail.py", line 12, in __init__
    self.connection = pymysql.connect(host=self.hostname, user=self.username, password=self.password,
  File "/usr/local/lib/python3.8/site-packages/pymysql/connections.py", line 353, in __init__
    self.connect()
  File "/usr/local/lib/python3.8/site-packages/pymysql/connections.py", line 664, in connect
    raise exc
pymysql.err.OperationalError: (2003, "Can't connect to MySQL server on 'backendqa0001.globo.correio.biz' (timed out)")

2021-08-10 01:11:06,599 - ERROR - An Error occurred while handling migrations: Traceback (most recent call last):
  File "/usr/local/lib/python3.8/site-packages/pymysql/connections.py", line 613, in connect
    sock = socket.create_connection(
  File "/usr/local/lib/python3.8/socket.py", line 808, in create_connection
    raise err
  File "/usr/local/lib/python3.8/socket.py", line 796, in create_connection
    sock.connect(sa)
socket.timeout: timed out

During handling of the above exception, another exception occurred:

Traceback (most recent call last):
  File "main.py", line 25, in handler_service
    handler_migration = IntegratorService(logger)
  File "/opt/globo/integrator/service.py", line 20, in __init__
    self.globomail_repository = GlobomailRepository()
  File "/opt/globo/repositories/globomail.py", line 12, in __init__
    self.connection = pymysql.connect(host=self.hostname, user=self.username, password=self.password,
  File "/usr/local/lib/python3.8/site-packages/pymysql/connections.py", line 353, in __init__
    self.connect()
  File "/usr/local/lib/python3.8/site-packages/pymysql/connections.py", line 664, in connect
    raise exc
pymysql.err.OperationalError: (2003, "Can't connect to MySQL server on 'backendqa0001.globo.correio.biz' (timed out)")

2021-08-10 01:12:16,916 - ERROR - An Error occurred while handling migrations: Traceback (most recent call last):
  File "/usr/local/lib/python3.8/site-packages/pymysql/connections.py", line 613, in connect
    sock = socket.create_connection(
  File "/usr/local/lib/python3.8/socket.py", line 808, in create_connection
    raise err
  File "/usr/local/lib/python3.8/socket.py", line 796, in create_connection
    sock.connect(sa)
socket.timeout: timed out

During handling of the above exception, another exception occurred:

Traceback (most recent call last):
  File "main.py", line 25, in handler_service
    handler_migration = IntegratorService(logger)
  File "/opt/globo/integrator/service.py", line 20, in __init__
    self.globomail_repository = GlobomailRepository()
  File "/opt/globo/repositories/globomail.py", line 12, in __init__
    self.connection = pymysql.connect(host=self.hostname, user=self.username, password=self.password,
  File "/usr/local/lib/python3.8/site-packages/pymysql/connections.py", line 353, in __init__
    self.connect()
  File "/usr/local/lib/python3.8/site-packages/pymysql/connections.py", line 664, in connect
    raise exc
pymysql.err.OperationalError: (2003, "Can't connect to MySQL server on 'backendqa0001.globo.correio.biz' (timed out)")

2021-08-10 01:13:27,255 - ERROR - An Error occurred while handling migrations: Traceback (most recent call last):
  File "/usr/local/lib/python3.8/site-packages/pymysql/connections.py", line 613, in connect
    sock = socket.create_connection(
  File "/usr/local/lib/python3.8/socket.py", line 808, in create_connection
    raise err
  File "/usr/local/lib/python3.8/socket.py", line 796, in create_connection
    sock.connect(sa)
socket.timeout: timed out

During handling of the above exception, another exception occurred:

Traceback (most recent call last):
  File "main.py", line 25, in handler_service
    handler_migration = IntegratorService(logger)
  File "/opt/globo/integrator/service.py", line 20, in __init__
    self.globomail_repository = GlobomailRepository()
  File "/opt/globo/repositories/globomail.py", line 12, in __init__
    self.connection = pymysql.connect(host=self.hostname, user=self.username, password=self.password,
  File "/usr/local/lib/python3.8/site-packages/pymysql/connections.py", line 353, in __init__
    self.connect()
  File "/usr/local/lib/python3.8/site-packages/pymysql/connections.py", line 664, in connect
    raise exc
pymysql.err.OperationalError: (2003, "Can't connect to MySQL server on 'backendqa0001.globo.correio.biz' (timed out)")

2021-08-10 01:14:37,542 - ERROR - An Error occurred while handling migrations: Traceback (most recent call last):
  File "/usr/local/lib/python3.8/site-packages/pymysql/connections.py", line 613, in connect
    sock = socket.create_connection(
  File "/usr/local/lib/python3.8/socket.py", line 808, in create_connection
    raise err
  File "/usr/local/lib/python3.8/socket.py", line 796, in create_connection
    sock.connect(sa)
socket.timeout: timed out

During handling of the above exception, another exception occurred:

Traceback (most recent call last):
  File "main.py", line 25, in handler_service
    handler_migration = IntegratorService(logger)
  File "/opt/globo/integrator/service.py", line 20, in __init__
    self.globomail_repository = GlobomailRepository()
  File "/opt/globo/repositories/globomail.py", line 12, in __init__
    self.connection = pymysql.connect(host=self.hostname, user=self.username, password=self.password,
  File "/usr/local/lib/python3.8/site-packages/pymysql/connections.py", line 353, in __init__
    self.connect()
  File "/usr/local/lib/python3.8/site-packages/pymysql/connections.py", line 664, in connect
    raise exc
pymysql.err.OperationalError: (2003, "Can't connect to MySQL server on 'backendqa0001.globo.correio.biz' (timed out)")

2021-08-10 01:15:48,113 - ERROR - An Error occurred while handling migrations: Traceback (most recent call last):
  File "/usr/local/lib/python3.8/site-packages/pymysql/connections.py", line 613, in connect
    sock = socket.create_connection(
  File "/usr/local/lib/python3.8/socket.py", line 808, in create_connection
    raise err
  File "/usr/local/lib/python3.8/socket.py", line 796, in create_connection
    sock.connect(sa)
socket.timeout: timed out

During handling of the above exception, another exception occurred:

Traceback (most recent call last):
  File "main.py", line 25, in handler_service
    handler_migration = IntegratorService(logger)
  File "/opt/globo/integrator/service.py", line 20, in __init__
    self.globomail_repository = GlobomailRepository()
  File "/opt/globo/repositories/globomail.py", line 12, in __init__
    self.connection = pymysql.connect(host=self.hostname, user=self.username, password=self.password,
  File "/usr/local/lib/python3.8/site-packages/pymysql/connections.py", line 353, in __init__
    self.connect()
  File "/usr/local/lib/python3.8/site-packages/pymysql/connections.py", line 664, in connect
    raise exc
pymysql.err.OperationalError: (2003, "Can't connect to MySQL server on 'backendqa0001.globo.correio.biz' (timed out)")

2021-08-10 01:16:58,443 - ERROR - An Error occurred while handling migrations: Traceback (most recent call last):
  File "/usr/local/lib/python3.8/site-packages/pymysql/connections.py", line 613, in connect
    sock = socket.create_connection(
  File "/usr/local/lib/python3.8/socket.py", line 808, in create_connection
    raise err
  File "/usr/local/lib/python3.8/socket.py", line 796, in create_connection
    sock.connect(sa)
socket.timeout: timed out

During handling of the above exception, another exception occurred:

Traceback (most recent call last):
  File "main.py", line 25, in handler_service
    handler_migration = IntegratorService(logger)
  File "/opt/globo/integrator/service.py", line 20, in __init__
    self.globomail_repository = GlobomailRepository()
  File "/opt/globo/repositories/globomail.py", line 12, in __init__
    self.connection = pymysql.connect(host=self.hostname, user=self.username, password=self.password,
  File "/usr/local/lib/python3.8/site-packages/pymysql/connections.py", line 353, in __init__
    self.connect()
  File "/usr/local/lib/python3.8/site-packages/pymysql/connections.py", line 664, in connect
    raise exc
pymysql.err.OperationalError: (2003, "Can't connect to MySQL server on 'backendqa0001.globo.correio.biz' (timed out)")

2021-08-10 01:18:08,773 - ERROR - An Error occurred while handling migrations: Traceback (most recent call last):
  File "/usr/local/lib/python3.8/site-packages/pymysql/connections.py", line 613, in connect
    sock = socket.create_connection(
  File "/usr/local/lib/python3.8/socket.py", line 808, in create_connection
    raise err
  File "/usr/local/lib/python3.8/socket.py", line 796, in create_connection
    sock.connect(sa)
socket.timeout: timed out

During handling of the above exception, another exception occurred:

Traceback (most recent call last):
  File "main.py", line 25, in handler_service
    handler_migration = IntegratorService(logger)
  File "/opt/globo/integrator/service.py", line 20, in __init__
    self.globomail_repository = GlobomailRepository()
  File "/opt/globo/repositories/globomail.py", line 12, in __init__
    self.connection = pymysql.connect(host=self.hostname, user=self.username, password=self.password,
  File "/usr/local/lib/python3.8/site-packages/pymysql/connections.py", line 353, in __init__
    self.connect()
  File "/usr/local/lib/python3.8/site-packages/pymysql/connections.py", line 664, in connect
    raise exc
pymysql.err.OperationalError: (2003, "Can't connect to MySQL server on 'backendqa0001.globo.correio.biz' (timed out)")

2021-08-10 01:19:19,809 - ERROR - An Error occurred while handling migrations: Traceback (most recent call last):
  File "/usr/local/lib/python3.8/site-packages/pymysql/connections.py", line 613, in connect
    sock = socket.create_connection(
  File "/usr/local/lib/python3.8/socket.py", line 808, in create_connection
    raise err
  File "/usr/local/lib/python3.8/socket.py", line 796, in create_connection
    sock.connect(sa)
socket.timeout: timed out

During handling of the above exception, another exception occurred:

Traceback (most recent call last):
  File "main.py", line 25, in handler_service
    handler_migration = IntegratorService(logger)
  File "/opt/globo/integrator/service.py", line 20, in __init__
    self.globomail_repository = GlobomailRepository()
  File "/opt/globo/repositories/globomail.py", line 12, in __init__
    self.connection = pymysql.connect(host=self.hostname, user=self.username, password=self.password,
  File "/usr/local/lib/python3.8/site-packages/pymysql/connections.py", line 353, in __init__
    self.connect()
  File "/usr/local/lib/python3.8/site-packages/pymysql/connections.py", line 664, in connect
    raise exc
pymysql.err.OperationalError: (2003, "Can't connect to MySQL server on 'backendqa0001.globo.correio.biz' (timed out)")

2021-08-10 01:20:30,161 - ERROR - An Error occurred while handling migrations: Traceback (most recent call last):
  File "/usr/local/lib/python3.8/site-packages/pymysql/connections.py", line 613, in connect
    sock = socket.create_connection(
  File "/usr/local/lib/python3.8/socket.py", line 808, in create_connection
    raise err
  File "/usr/local/lib/python3.8/socket.py", line 796, in create_connection
    sock.connect(sa)
socket.timeout: timed out

During handling of the above exception, another exception occurred:

Traceback (most recent call last):
  File "main.py", line 25, in handler_service
    handler_migration = IntegratorService(logger)
  File "/opt/globo/integrator/service.py", line 20, in __init__
    self.globomail_repository = GlobomailRepository()
  File "/opt/globo/repositories/globomail.py", line 12, in __init__
    self.connection = pymysql.connect(host=self.hostname, user=self.username, password=self.password,
  File "/usr/local/lib/python3.8/site-packages/pymysql/connections.py", line 353, in __init__
    self.connect()
  File "/usr/local/lib/python3.8/site-packages/pymysql/connections.py", line 664, in connect
    raise exc
pymysql.err.OperationalError: (2003, "Can't connect to MySQL server on 'backendqa0001.globo.correio.biz' (timed out)")

2021-08-10 01:21:40,571 - ERROR - An Error occurred while handling migrations: Traceback (most recent call last):
  File "/usr/local/lib/python3.8/site-packages/pymysql/connections.py", line 613, in connect
    sock = socket.create_connection(
  File "/usr/local/lib/python3.8/socket.py", line 808, in create_connection
    raise err
  File "/usr/local/lib/python3.8/socket.py", line 796, in create_connection
    sock.connect(sa)
socket.timeout: timed out

During handling of the above exception, another exception occurred:

Traceback (most recent call last):
  File "main.py", line 25, in handler_service
    handler_migration = IntegratorService(logger)
  File "/opt/globo/integrator/service.py", line 20, in __init__
    self.globomail_repository = GlobomailRepository()
  File "/opt/globo/repositories/globomail.py", line 12, in __init__
    self.connection = pymysql.connect(host=self.hostname, user=self.username, password=self.password,
  File "/usr/local/lib/python3.8/site-packages/pymysql/connections.py", line 353, in __init__
    self.connect()
  File "/usr/local/lib/python3.8/site-packages/pymysql/connections.py", line 664, in connect
    raise exc
pymysql.err.OperationalError: (2003, "Can't connect to MySQL server on 'backendqa0001.globo.correio.biz' (timed out)")

2021-08-10 02:05:34,461 - ERROR - An Error occurred while handling migrations: Traceback (most recent call last):
  File "/usr/local/lib/python3.8/site-packages/pymysql/connections.py", line 613, in connect
    sock = socket.create_connection(
  File "/usr/local/lib/python3.8/socket.py", line 787, in create_connection
    for res in getaddrinfo(host, port, 0, SOCK_STREAM):
  File "/usr/local/lib/python3.8/socket.py", line 918, in getaddrinfo
    for res in _socket.getaddrinfo(host, port, family, type, proto, flags):
socket.gaierror: [Errno -2] Name or service not known

During handling of the above exception, another exception occurred:

Traceback (most recent call last):
  File "main.py", line 25, in handler_service
    handler_migration = IntegratorService(logger)
  File "/opt/globo/integrator/service.py", line 20, in __init__
    self.globomail_repository = GlobomailRepository()
  File "/opt/globo/repositories/globomail.py", line 12, in __init__
    self.connection = pymysql.connect(host=self.hostname, user=self.username, password=self.password,
  File "/usr/local/lib/python3.8/site-packages/pymysql/connections.py", line 353, in __init__
    self.connect()
  File "/usr/local/lib/python3.8/site-packages/pymysql/connections.py", line 664, in connect
    raise exc
pymysql.err.OperationalError: (2003, "Can't connect to MySQL server on 'backendqa0001.globo.correio.biz' ([Errno -2] Name or service not known)")

2021-08-10 02:27:46,412 - ERROR - An Error occurred while handling migrations: Traceback (most recent call last):
  File "/usr/local/lib/python3.8/site-packages/pymysql/connections.py", line 613, in connect
    sock = socket.create_connection(
  File "/usr/local/lib/python3.8/socket.py", line 808, in create_connection
    raise err
  File "/usr/local/lib/python3.8/socket.py", line 796, in create_connection
    sock.connect(sa)
socket.timeout: timed out

During handling of the above exception, another exception occurred:

Traceback (most recent call last):
  File "main.py", line 25, in handler_service
    handler_migration = IntegratorService(logger)
  File "/opt/globo/integrator/service.py", line 20, in __init__
    self.globomail_repository = GlobomailRepository()
  File "/opt/globo/repositories/globomail.py", line 12, in __init__
    self.connection = pymysql.connect(host=self.hostname, user=self.username, password=self.password,
  File "/usr/local/lib/python3.8/site-packages/pymysql/connections.py", line 353, in __init__
    self.connect()
  File "/usr/local/lib/python3.8/site-packages/pymysql/connections.py", line 664, in connect
    raise exc
pymysql.err.OperationalError: (2003, "Can't connect to MySQL server on 'backendqa0001.globo.correio.biz' (timed out)")

2021-08-10 02:28:46,913 - ERROR - An Error occurred while handling migrations: Traceback (most recent call last):
  File "/usr/local/lib/python3.8/site-packages/pymysql/connections.py", line 613, in connect
    sock = socket.create_connection(
  File "/usr/local/lib/python3.8/socket.py", line 787, in create_connection
    for res in getaddrinfo(host, port, 0, SOCK_STREAM):
  File "/usr/local/lib/python3.8/socket.py", line 918, in getaddrinfo
    for res in _socket.getaddrinfo(host, port, family, type, proto, flags):
socket.gaierror: [Errno -2] Name or service not known

During handling of the above exception, another exception occurred:

Traceback (most recent call last):
  File "main.py", line 25, in handler_service
    handler_migration = IntegratorService(logger)
  File "/opt/globo/integrator/service.py", line 20, in __init__
    self.globomail_repository = GlobomailRepository()
  File "/opt/globo/repositories/globomail.py", line 12, in __init__
    self.connection = pymysql.connect(host=self.hostname, user=self.username, password=self.password,
  File "/usr/local/lib/python3.8/site-packages/pymysql/connections.py", line 353, in __init__
    self.connect()
  File "/usr/local/lib/python3.8/site-packages/pymysql/connections.py", line 664, in connect
    raise exc
pymysql.err.OperationalError: (2003, "Can't connect to MySQL server on 'backendqa0001.globo.correio.biz' ([Errno -2] Name or service not known)")

2021-08-10 02:58:42,183 - ERROR - An Error occurred while handling migrations: Traceback (most recent call last):
  File "/usr/local/lib/python3.8/site-packages/pymysql/connections.py", line 613, in connect
    sock = socket.create_connection(
  File "/usr/local/lib/python3.8/socket.py", line 787, in create_connection
    for res in getaddrinfo(host, port, 0, SOCK_STREAM):
  File "/usr/local/lib/python3.8/socket.py", line 918, in getaddrinfo
    for res in _socket.getaddrinfo(host, port, family, type, proto, flags):
socket.gaierror: [Errno -2] Name or service not known

During handling of the above exception, another exception occurred:

Traceback (most recent call last):
  File "main.py", line 25, in handler_service
    handler_migration = IntegratorService(logger)
  File "/opt/globo/integrator/service.py", line 20, in __init__
    self.globomail_repository = GlobomailRepository()
  File "/opt/globo/repositories/globomail.py", line 12, in __init__
    self.connection = pymysql.connect(host=self.hostname, user=self.username, password=self.password,
  File "/usr/local/lib/python3.8/site-packages/pymysql/connections.py", line 353, in __init__
    self.connect()
  File "/usr/local/lib/python3.8/site-packages/pymysql/connections.py", line 664, in connect
    raise exc
pymysql.err.OperationalError: (2003, "Can't connect to MySQL server on 'backendqa0001.globo.correio.biz' ([Errno -2] Name or service not known)")

2021-08-10 03:05:12,061 - ERROR - An Error occurred while handling migrations: Traceback (most recent call last):
  File "/usr/local/lib/python3.8/site-packages/pymysql/connections.py", line 613, in connect
    sock = socket.create_connection(
  File "/usr/local/lib/python3.8/socket.py", line 787, in create_connection
    for res in getaddrinfo(host, port, 0, SOCK_STREAM):
  File "/usr/local/lib/python3.8/socket.py", line 918, in getaddrinfo
    for res in _socket.getaddrinfo(host, port, family, type, proto, flags):
socket.gaierror: [Errno -2] Name or service not known

During handling of the above exception, another exception occurred:

Traceback (most recent call last):
  File "main.py", line 25, in handler_service
    handler_migration = IntegratorService(logger)
  File "/opt/globo/integrator/service.py", line 20, in __init__
    self.globomail_repository = GlobomailRepository()
  File "/opt/globo/repositories/globomail.py", line 12, in __init__
    self.connection = pymysql.connect(host=self.hostname, user=self.username, password=self.password,
  File "/usr/local/lib/python3.8/site-packages/pymysql/connections.py", line 353, in __init__
    self.connect()
  File "/usr/local/lib/python3.8/site-packages/pymysql/connections.py", line 664, in connect
    raise exc
pymysql.err.OperationalError: (2003, "Can't connect to MySQL server on 'backendqa0001.globo.correio.biz' ([Errno -2] Name or service not known)")

2021-08-10 03:23:48,284 - ERROR - An Error occurred while handling migrations: Traceback (most recent call last):
  File "/usr/local/lib/python3.8/site-packages/pymysql/connections.py", line 613, in connect
    sock = socket.create_connection(
  File "/usr/local/lib/python3.8/socket.py", line 808, in create_connection
    raise err
  File "/usr/local/lib/python3.8/socket.py", line 796, in create_connection
    sock.connect(sa)
socket.timeout: timed out

During handling of the above exception, another exception occurred:

Traceback (most recent call last):
  File "main.py", line 25, in handler_service
    handler_migration = IntegratorService(logger)
  File "/opt/globo/integrator/service.py", line 20, in __init__
    self.globomail_repository = GlobomailRepository()
  File "/opt/globo/repositories/globomail.py", line 12, in __init__
    self.connection = pymysql.connect(host=self.hostname, user=self.username, password=self.password,
  File "/usr/local/lib/python3.8/site-packages/pymysql/connections.py", line 353, in __init__
    self.connect()
  File "/usr/local/lib/python3.8/site-packages/pymysql/connections.py", line 664, in connect
    raise exc
pymysql.err.OperationalError: (2003, "Can't connect to MySQL server on 'backendqa0001.globo.correio.biz' (timed out)")

2021-08-10 04:27:45,883 - ERROR - An Error occurred while handling migrations: Traceback (most recent call last):
  File "/usr/local/lib/python3.8/site-packages/pymysql/connections.py", line 613, in connect
    sock = socket.create_connection(
  File "/usr/local/lib/python3.8/socket.py", line 808, in create_connection
    raise err
  File "/usr/local/lib/python3.8/socket.py", line 796, in create_connection
    sock.connect(sa)
socket.timeout: timed out

During handling of the above exception, another exception occurred:

Traceback (most recent call last):
  File "main.py", line 25, in handler_service
    handler_migration = IntegratorService(logger)
  File "/opt/globo/integrator/service.py", line 20, in __init__
    self.globomail_repository = GlobomailRepository()
  File "/opt/globo/repositories/globomail.py", line 12, in __init__
    self.connection = pymysql.connect(host=self.hostname, user=self.username, password=self.password,
  File "/usr/local/lib/python3.8/site-packages/pymysql/connections.py", line 353, in __init__
    self.connect()
  File "/usr/local/lib/python3.8/site-packages/pymysql/connections.py", line 664, in connect
    raise exc
pymysql.err.OperationalError: (2003, "Can't connect to MySQL server on 'backendqa0001.globo.correio.biz' (timed out)")

2021-08-10 05:36:31,171 - ERROR - An Error occurred while handling migrations: Traceback (most recent call last):
  File "/usr/local/lib/python3.8/site-packages/pymysql/connections.py", line 613, in connect
    sock = socket.create_connection(
  File "/usr/local/lib/python3.8/socket.py", line 808, in create_connection
    raise err
  File "/usr/local/lib/python3.8/socket.py", line 796, in create_connection
    sock.connect(sa)
ConnectionRefusedError: [Errno 111] Connection refused

During handling of the above exception, another exception occurred:

Traceback (most recent call last):
  File "main.py", line 25, in handler_service
    handler_migration = IntegratorService(logger)
  File "/opt/globo/integrator/service.py", line 20, in __init__
    self.globomail_repository = GlobomailRepository()
  File "/opt/globo/repositories/globomail.py", line 12, in __init__
    self.connection = pymysql.connect(host=self.hostname, user=self.username, password=self.password,
  File "/usr/local/lib/python3.8/site-packages/pymysql/connections.py", line 353, in __init__
    self.connect()
  File "/usr/local/lib/python3.8/site-packages/pymysql/connections.py", line 664, in connect
    raise exc
pymysql.err.OperationalError: (2003, "Can't connect to MySQL server on 'backendqa0001.globo.correio.biz' ([Errno 111] Connection refused)")

2021-08-10 06:25:04,456 - ERROR - An Error occurred while handling migrations: Traceback (most recent call last):
  File "/usr/local/lib/python3.8/site-packages/pymysql/connections.py", line 613, in connect
    sock = socket.create_connection(
  File "/usr/local/lib/python3.8/socket.py", line 808, in create_connection
    raise err
  File "/usr/local/lib/python3.8/socket.py", line 796, in create_connection
    sock.connect(sa)
ConnectionRefusedError: [Errno 111] Connection refused

During handling of the above exception, another exception occurred:

Traceback (most recent call last):
  File "main.py", line 25, in handler_service
    handler_migration = IntegratorService(logger)
  File "/opt/globo/integrator/service.py", line 20, in __init__
    self.globomail_repository = GlobomailRepository()
  File "/opt/globo/repositories/globomail.py", line 12, in __init__
    self.connection = pymysql.connect(host=self.hostname, user=self.username, password=self.password,
  File "/usr/local/lib/python3.8/site-packages/pymysql/connections.py", line 353, in __init__
    self.connect()
  File "/usr/local/lib/python3.8/site-packages/pymysql/connections.py", line 664, in connect
    raise exc
pymysql.err.OperationalError: (2003, "Can't connect to MySQL server on 'backendqa0001.globo.correio.biz' ([Errno 111] Connection refused)")

2021-08-10 07:28:41,978 - ERROR - An Error occurred while handling migrations: Traceback (most recent call last):
  File "/usr/local/lib/python3.8/site-packages/pymysql/connections.py", line 613, in connect
    sock = socket.create_connection(
  File "/usr/local/lib/python3.8/socket.py", line 808, in create_connection
    raise err
  File "/usr/local/lib/python3.8/socket.py", line 796, in create_connection
    sock.connect(sa)
ConnectionRefusedError: [Errno 111] Connection refused

During handling of the above exception, another exception occurred:

Traceback (most recent call last):
  File "main.py", line 25, in handler_service
    handler_migration = IntegratorService(logger)
  File "/opt/globo/integrator/service.py", line 20, in __init__
    self.globomail_repository = GlobomailRepository()
  File "/opt/globo/repositories/globomail.py", line 12, in __init__
    self.connection = pymysql.connect(host=self.hostname, user=self.username, password=self.password,
  File "/usr/local/lib/python3.8/site-packages/pymysql/connections.py", line 353, in __init__
    self.connect()
  File "/usr/local/lib/python3.8/site-packages/pymysql/connections.py", line 664, in connect
    raise exc
pymysql.err.OperationalError: (2003, "Can't connect to MySQL server on 'backendqa0001.globo.correio.biz' ([Errno 111] Connection refused)")

2021-08-10 08:51:44,060 - ERROR - An Error occurred while handling migrations: Traceback (most recent call last):
  File "/usr/local/lib/python3.8/site-packages/pymysql/connections.py", line 613, in connect
    sock = socket.create_connection(
  File "/usr/local/lib/python3.8/socket.py", line 808, in create_connection
    raise err
  File "/usr/local/lib/python3.8/socket.py", line 796, in create_connection
    sock.connect(sa)
ConnectionRefusedError: [Errno 111] Connection refused

During handling of the above exception, another exception occurred:

Traceback (most recent call last):
  File "main.py", line 25, in handler_service
    handler_migration = IntegratorService(logger)
  File "/opt/globo/integrator/service.py", line 20, in __init__
    self.globomail_repository = GlobomailRepository()
  File "/opt/globo/repositories/globomail.py", line 12, in __init__
    self.connection = pymysql.connect(host=self.hostname, user=self.username, password=self.password,
  File "/usr/local/lib/python3.8/site-packages/pymysql/connections.py", line 353, in __init__
    self.connect()
  File "/usr/local/lib/python3.8/site-packages/pymysql/connections.py", line 664, in connect
    raise exc
pymysql.err.OperationalError: (2003, "Can't connect to MySQL server on 'backendqa0001.globo.correio.biz' ([Errno 111] Connection refused)")

2021-08-10 09:36:56,072 - ERROR - An Error occurred while handling migrations: Traceback (most recent call last):
  File "/usr/local/lib/python3.8/site-packages/pymysql/connections.py", line 613, in connect
    sock = socket.create_connection(
  File "/usr/local/lib/python3.8/socket.py", line 808, in create_connection
    raise err
  File "/usr/local/lib/python3.8/socket.py", line 796, in create_connection
    sock.connect(sa)
socket.timeout: timed out

During handling of the above exception, another exception occurred:

Traceback (most recent call last):
  File "main.py", line 25, in handler_service
    handler_migration = IntegratorService(logger)
  File "/opt/globo/integrator/service.py", line 20, in __init__
    self.globomail_repository = GlobomailRepository()
  File "/opt/globo/repositories/globomail.py", line 12, in __init__
    self.connection = pymysql.connect(host=self.hostname, user=self.username, password=self.password,
  File "/usr/local/lib/python3.8/site-packages/pymysql/connections.py", line 353, in __init__
    self.connect()
  File "/usr/local/lib/python3.8/site-packages/pymysql/connections.py", line 664, in connect
    raise exc
pymysql.err.OperationalError: (2003, "Can't connect to MySQL server on 'backendqa0001.globo.correio.biz' (timed out)")

2021-08-10 09:38:06,560 - ERROR - An Error occurred while handling migrations: Traceback (most recent call last):
  File "/usr/local/lib/python3.8/site-packages/pymysql/connections.py", line 613, in connect
    sock = socket.create_connection(
  File "/usr/local/lib/python3.8/socket.py", line 808, in create_connection
    raise err
  File "/usr/local/lib/python3.8/socket.py", line 796, in create_connection
    sock.connect(sa)
socket.timeout: timed out

During handling of the above exception, another exception occurred:

Traceback (most recent call last):
  File "main.py", line 25, in handler_service
    handler_migration = IntegratorService(logger)
  File "/opt/globo/integrator/service.py", line 20, in __init__
    self.globomail_repository = GlobomailRepository()
  File "/opt/globo/repositories/globomail.py", line 12, in __init__
    self.connection = pymysql.connect(host=self.hostname, user=self.username, password=self.password,
  File "/usr/local/lib/python3.8/site-packages/pymysql/connections.py", line 353, in __init__
    self.connect()
  File "/usr/local/lib/python3.8/site-packages/pymysql/connections.py", line 664, in connect
    raise exc
pymysql.err.OperationalError: (2003, "Can't connect to MySQL server on 'backendqa0001.globo.correio.biz' (timed out)")

2021-08-10 10:10:47,923 - ERROR - An Error occurred while handling migrations: Traceback (most recent call last):
  File "/usr/local/lib/python3.8/site-packages/pymysql/connections.py", line 613, in connect
    sock = socket.create_connection(
  File "/usr/local/lib/python3.8/socket.py", line 808, in create_connection
    raise err
  File "/usr/local/lib/python3.8/socket.py", line 796, in create_connection
    sock.connect(sa)
socket.timeout: timed out

During handling of the above exception, another exception occurred:

Traceback (most recent call last):
  File "main.py", line 25, in handler_service
    handler_migration = IntegratorService(logger)
  File "/opt/globo/integrator/service.py", line 20, in __init__
    self.globomail_repository = GlobomailRepository()
  File "/opt/globo/repositories/globomail.py", line 12, in __init__
    self.connection = pymysql.connect(host=self.hostname, user=self.username, password=self.password,
  File "/usr/local/lib/python3.8/site-packages/pymysql/connections.py", line 353, in __init__
    self.connect()
  File "/usr/local/lib/python3.8/site-packages/pymysql/connections.py", line 664, in connect
    raise exc
pymysql.err.OperationalError: (2003, "Can't connect to MySQL server on 'backendqa0001.globo.correio.biz' (timed out)")

2021-08-10 10:43:44,783 - ERROR - An Error occurred while handling migrations: Traceback (most recent call last):
  File "/usr/local/lib/python3.8/site-packages/pymysql/connections.py", line 613, in connect
    sock = socket.create_connection(
  File "/usr/local/lib/python3.8/socket.py", line 808, in create_connection
    raise err
  File "/usr/local/lib/python3.8/socket.py", line 796, in create_connection
    sock.connect(sa)
socket.timeout: timed out

During handling of the above exception, another exception occurred:

Traceback (most recent call last):
  File "main.py", line 25, in handler_service
    handler_migration = IntegratorService(logger)
  File "/opt/globo/integrator/service.py", line 20, in __init__
    self.globomail_repository = GlobomailRepository()
  File "/opt/globo/repositories/globomail.py", line 12, in __init__
    self.connection = pymysql.connect(host=self.hostname, user=self.username, password=self.password,
  File "/usr/local/lib/python3.8/site-packages/pymysql/connections.py", line 353, in __init__
    self.connect()
  File "/usr/local/lib/python3.8/site-packages/pymysql/connections.py", line 664, in connect
    raise exc
pymysql.err.OperationalError: (2003, "Can't connect to MySQL server on 'backendqa0001.globo.correio.biz' (timed out)")

2021-08-10 10:50:09,459 - ERROR - An Error occurred while handling migrations: Traceback (most recent call last):
  File "/usr/local/lib/python3.8/site-packages/pymysql/connections.py", line 613, in connect
    sock = socket.create_connection(
  File "/usr/local/lib/python3.8/socket.py", line 808, in create_connection
    raise err
  File "/usr/local/lib/python3.8/socket.py", line 796, in create_connection
    sock.connect(sa)
socket.timeout: timed out

During handling of the above exception, another exception occurred:

Traceback (most recent call last):
  File "main.py", line 25, in handler_service
    handler_migration = IntegratorService(logger)
  File "/opt/globo/integrator/service.py", line 20, in __init__
    self.globomail_repository = GlobomailRepository()
  File "/opt/globo/repositories/globomail.py", line 12, in __init__
    self.connection = pymysql.connect(host=self.hostname, user=self.username, password=self.password,
  File "/usr/local/lib/python3.8/site-packages/pymysql/connections.py", line 353, in __init__
    self.connect()
  File "/usr/local/lib/python3.8/site-packages/pymysql/connections.py", line 664, in connect
    raise exc
pymysql.err.OperationalError: (2003, "Can't connect to MySQL server on 'backendqa0001.globo.correio.biz' (timed out)")

2021-08-10 10:51:19,938 - ERROR - An Error occurred while handling migrations: Traceback (most recent call last):
  File "/usr/local/lib/python3.8/site-packages/pymysql/connections.py", line 613, in connect
    sock = socket.create_connection(
  File "/usr/local/lib/python3.8/socket.py", line 808, in create_connection
    raise err
  File "/usr/local/lib/python3.8/socket.py", line 796, in create_connection
    sock.connect(sa)
socket.timeout: timed out

During handling of the above exception, another exception occurred:

Traceback (most recent call last):
  File "main.py", line 25, in handler_service
    handler_migration = IntegratorService(logger)
  File "/opt/globo/integrator/service.py", line 20, in __init__
    self.globomail_repository = GlobomailRepository()
  File "/opt/globo/repositories/globomail.py", line 12, in __init__
    self.connection = pymysql.connect(host=self.hostname, user=self.username, password=self.password,
  File "/usr/local/lib/python3.8/site-packages/pymysql/connections.py", line 353, in __init__
    self.connect()
  File "/usr/local/lib/python3.8/site-packages/pymysql/connections.py", line 664, in connect
    raise exc
pymysql.err.OperationalError: (2003, "Can't connect to MySQL server on 'backendqa0001.globo.correio.biz' (timed out)")

2021-08-10 11:42:18,740 - ERROR - An Error occurred while handling migrations: Traceback (most recent call last):
  File "/usr/local/lib/python3.8/site-packages/pymysql/connections.py", line 613, in connect
    sock = socket.create_connection(
  File "/usr/local/lib/python3.8/socket.py", line 808, in create_connection
    raise err
  File "/usr/local/lib/python3.8/socket.py", line 796, in create_connection
    sock.connect(sa)
socket.timeout: timed out

During handling of the above exception, another exception occurred:

Traceback (most recent call last):
  File "main.py", line 25, in handler_service
    handler_migration = IntegratorService(logger)
  File "/opt/globo/integrator/service.py", line 20, in __init__
    self.globomail_repository = GlobomailRepository()
  File "/opt/globo/repositories/globomail.py", line 12, in __init__
    self.connection = pymysql.connect(host=self.hostname, user=self.username, password=self.password,
  File "/usr/local/lib/python3.8/site-packages/pymysql/connections.py", line 353, in __init__
    self.connect()
  File "/usr/local/lib/python3.8/site-packages/pymysql/connections.py", line 664, in connect
    raise exc
pymysql.err.OperationalError: (2003, "Can't connect to MySQL server on 'backendqa0001.globo.correio.biz' (timed out)")

2021-08-10 11:45:32,959 - ERROR - An Error occurred while handling migrations: Traceback (most recent call last):
  File "/usr/local/lib/python3.8/site-packages/pymysql/connections.py", line 613, in connect
    sock = socket.create_connection(
  File "/usr/local/lib/python3.8/socket.py", line 808, in create_connection
    raise err
  File "/usr/local/lib/python3.8/socket.py", line 796, in create_connection
    sock.connect(sa)
socket.timeout: timed out

During handling of the above exception, another exception occurred:

Traceback (most recent call last):
  File "main.py", line 25, in handler_service
    handler_migration = IntegratorService(logger)
  File "/opt/globo/integrator/service.py", line 20, in __init__
    self.globomail_repository = GlobomailRepository()
  File "/opt/globo/repositories/globomail.py", line 12, in __init__
    self.connection = pymysql.connect(host=self.hostname, user=self.username, password=self.password,
  File "/usr/local/lib/python3.8/site-packages/pymysql/connections.py", line 353, in __init__
    self.connect()
  File "/usr/local/lib/python3.8/site-packages/pymysql/connections.py", line 664, in connect
    raise exc
pymysql.err.OperationalError: (2003, "Can't connect to MySQL server on 'backendqa0001.globo.correio.biz' (timed out)")

2021-08-10 11:46:43,477 - ERROR - An Error occurred while handling migrations: Traceback (most recent call last):
  File "/usr/local/lib/python3.8/site-packages/pymysql/connections.py", line 613, in connect
    sock = socket.create_connection(
  File "/usr/local/lib/python3.8/socket.py", line 808, in create_connection
    raise err
  File "/usr/local/lib/python3.8/socket.py", line 796, in create_connection
    sock.connect(sa)
socket.timeout: timed out

During handling of the above exception, another exception occurred:

Traceback (most recent call last):
  File "main.py", line 25, in handler_service
    handler_migration = IntegratorService(logger)
  File "/opt/globo/integrator/service.py", line 20, in __init__
    self.globomail_repository = GlobomailRepository()
  File "/opt/globo/repositories/globomail.py", line 12, in __init__
    self.connection = pymysql.connect(host=self.hostname, user=self.username, password=self.password,
  File "/usr/local/lib/python3.8/site-packages/pymysql/connections.py", line 353, in __init__
    self.connect()
  File "/usr/local/lib/python3.8/site-packages/pymysql/connections.py", line 664, in connect
    raise exc
pymysql.err.OperationalError: (2003, "Can't connect to MySQL server on 'backendqa0001.globo.correio.biz' (timed out)")

2021-08-10 11:47:53,781 - ERROR - An Error occurred while handling migrations: Traceback (most recent call last):
  File "/usr/local/lib/python3.8/site-packages/pymysql/connections.py", line 613, in connect
    sock = socket.create_connection(
  File "/usr/local/lib/python3.8/socket.py", line 808, in create_connection
    raise err
  File "/usr/local/lib/python3.8/socket.py", line 796, in create_connection
    sock.connect(sa)
socket.timeout: timed out

During handling of the above exception, another exception occurred:

Traceback (most recent call last):
  File "main.py", line 25, in handler_service
    handler_migration = IntegratorService(logger)
  File "/opt/globo/integrator/service.py", line 20, in __init__
    self.globomail_repository = GlobomailRepository()
  File "/opt/globo/repositories/globomail.py", line 12, in __init__
    self.connection = pymysql.connect(host=self.hostname, user=self.username, password=self.password,
  File "/usr/local/lib/python3.8/site-packages/pymysql/connections.py", line 353, in __init__
    self.connect()
  File "/usr/local/lib/python3.8/site-packages/pymysql/connections.py", line 664, in connect
    raise exc
pymysql.err.OperationalError: (2003, "Can't connect to MySQL server on 'backendqa0001.globo.correio.biz' (timed out)")

2021-08-10 11:49:04,189 - ERROR - An Error occurred while handling migrations: Traceback (most recent call last):
  File "/usr/local/lib/python3.8/site-packages/pymysql/connections.py", line 613, in connect
    sock = socket.create_connection(
  File "/usr/local/lib/python3.8/socket.py", line 808, in create_connection
    raise err
  File "/usr/local/lib/python3.8/socket.py", line 796, in create_connection
    sock.connect(sa)
socket.timeout: timed out

During handling of the above exception, another exception occurred:

Traceback (most recent call last):
  File "main.py", line 25, in handler_service
    handler_migration = IntegratorService(logger)
  File "/opt/globo/integrator/service.py", line 20, in __init__
    self.globomail_repository = GlobomailRepository()
  File "/opt/globo/repositories/globomail.py", line 12, in __init__
    self.connection = pymysql.connect(host=self.hostname, user=self.username, password=self.password,
  File "/usr/local/lib/python3.8/site-packages/pymysql/connections.py", line 353, in __init__
    self.connect()
  File "/usr/local/lib/python3.8/site-packages/pymysql/connections.py", line 664, in connect
    raise exc
pymysql.err.OperationalError: (2003, "Can't connect to MySQL server on 'backendqa0001.globo.correio.biz' (timed out)")

2021-08-10 11:50:14,731 - ERROR - An Error occurred while handling migrations: Traceback (most recent call last):
  File "/usr/local/lib/python3.8/site-packages/pymysql/connections.py", line 613, in connect
    sock = socket.create_connection(
  File "/usr/local/lib/python3.8/socket.py", line 808, in create_connection
    raise err
  File "/usr/local/lib/python3.8/socket.py", line 796, in create_connection
    sock.connect(sa)
socket.timeout: timed out

During handling of the above exception, another exception occurred:

Traceback (most recent call last):
  File "main.py", line 25, in handler_service
    handler_migration = IntegratorService(logger)
  File "/opt/globo/integrator/service.py", line 20, in __init__
    self.globomail_repository = GlobomailRepository()
  File "/opt/globo/repositories/globomail.py", line 12, in __init__
    self.connection = pymysql.connect(host=self.hostname, user=self.username, password=self.password,
  File "/usr/local/lib/python3.8/site-packages/pymysql/connections.py", line 353, in __init__
    self.connect()
  File "/usr/local/lib/python3.8/site-packages/pymysql/connections.py", line 664, in connect
    raise exc
pymysql.err.OperationalError: (2003, "Can't connect to MySQL server on 'backendqa0001.globo.correio.biz' (timed out)")

2021-08-10 11:57:25,183 - ERROR - An Error occurred while handling migrations: Traceback (most recent call last):
  File "/usr/local/lib/python3.8/site-packages/pymysql/connections.py", line 613, in connect
    sock = socket.create_connection(
  File "/usr/local/lib/python3.8/socket.py", line 808, in create_connection
    raise err
  File "/usr/local/lib/python3.8/socket.py", line 796, in create_connection
    sock.connect(sa)
socket.timeout: timed out

During handling of the above exception, another exception occurred:

Traceback (most recent call last):
  File "main.py", line 25, in handler_service
    handler_migration = IntegratorService(logger)
  File "/opt/globo/integrator/service.py", line 20, in __init__
    self.globomail_repository = GlobomailRepository()
  File "/opt/globo/repositories/globomail.py", line 12, in __init__
    self.connection = pymysql.connect(host=self.hostname, user=self.username, password=self.password,
  File "/usr/local/lib/python3.8/site-packages/pymysql/connections.py", line 353, in __init__
    self.connect()
  File "/usr/local/lib/python3.8/site-packages/pymysql/connections.py", line 664, in connect
    raise exc
pymysql.err.OperationalError: (2003, "Can't connect to MySQL server on 'backendqa0001.globo.correio.biz' (timed out)")

